Workbook
Name IDEB09_R_Fim_Esc8a: 'IDEB_Escolas (Anos_Finais)'!$A$11:$DK$43

Sheet IDEB_Escolas (Anos_Finais)
C1: Ministério da Educação
C2: Instituto Nacional de Estudos e Pesquisas Educacionais Anísio Teixeira
A4: Ensino Fundamental Regular - Anos Finais
A5: Indicadores educacionais compostos por: Taxa de Aprovação, SAEB e IDEB nos anos de 2005, 2007, 2009, 2011, 2013, 2015, 2017, 2019, 20211 e 2023 e Metas do 1º ciclo do Ideb2,3 (2007-2021). Os dados estão dimensionados por escola e organizados por rede de ensino.
A7: Sigla da UF | B7: Código do Município | C7: Nome do Município | E7: Código da Escola | F7: Nome da Escola | G7: Rede | H7: Taxa de Aprovação - 2005 | N7: Taxa de Aprovação - 2007 | T7: Taxa de Aprovação - 2009 | Z7: Taxa de Aprovação - 2011 | AF7: Taxa de Aprovação - 2013 | AL7: Taxa de Aprovação - 2015 | AR7: Taxa de Aprovação - 2017 | AX7: Taxa de Aprovação - 2019 | BD7: Taxa de Aprovação - 20211 | BJ7: Taxa de Aprovação - 2023 | BP7: Nota SAEB - 2005 | BS7: Nota SAEB - 2007 | BV7: Nota SAEB - 2009 | BY7: Nota SAEB - 2011 | CB7: Nota SAEB - 2013 | CE7: Nota SAEB - 2015 | CH7: Nota SAEB - 2017 | CK7: Nota SAEB - 2019 | CN7: Nota SAEB - 20211 | CQ7: Nota SAEB - 2023 | CT7: IDEB 2005 (N x P) | CU7: IDEB 2007 (N x P) | CV7: IDEB 2009 (N x P) | CW7: IDEB 2011 (N x P) | CX7: IDEB 2013 (N x P) | CY7: IDEB 2015 (N x P) | CZ7: IDEB 2017 (N x P) | DA7: IDEB 2019 (N x P) | DB7: IDEB 20211 (N x P) | DC7: IDEB 2023 (N x P) | DD7: Metas do 1º ciclo do Ideb2,3 (2007-2021)
BP8: Matemática | BQ8: Língua Portuguesa | BR8: Nota Média Padronizada (N) | BS8: Matemática | BT8: Língua Portuguesa | BU8: Nota Média Padronizada (N) | BV8: Matemática | BW8: Língua Portuguesa | BX8: Nota Média Padronizada (N) | BY8: Matemática | BZ8: Língua Portuguesa | CA8: Nota Média Padronizada (N) | CB8: Matemática | CC8: Língua Portuguesa | CD8: Nota Média Padronizada (N) | CE8: Matemática | CF8: Língua Portuguesa | CG8: Nota Média Padronizada (N) | CH8: Matemática | CI8: Língua Portuguesa | CJ8: Nota Média Padronizada (N) | CK8: Matemática | CL8: Língua Portuguesa | CM8: Nota Média Padronizada (N) | CN8: Matemática | CO8: Língua Portuguesa | CP8: Nota Média Padronizada (N) | CQ8: Matemática | CR8: Língua Portuguesa | CS8: Nota Média Padronizada (N)
H9: 6º a 9º ano | I9: 6º | J9: 7º | K9: 8º | L9: 9º | M9: Indicador de Rendimento (P) | N9: 6º a 9º ano | O9: 6º | P9: 7º | Q9: 8º | R9: 9º | S9: Indicador de Rendimento (P) | T9: 6º a 9º ano | U9: 6º | V9: 7º | W9: 8º | X9: 9º | Y9: Indicador de Rendimento (P) | Z9: 6º a 9º ano | AA9: 6º | AB9: 7º | AC9: 8º | AD9: 9º | AE9: Indicador de Rendimento (P) | AF9: 6º a 9º ano | AG9: 6º | AH9: 7º | AI9: 8º | AJ9: 9º | AK9: Indicador de Rendimento (P) | AL9: 6º a 9º ano | AM9: 6º | AN9: 7º | AO9: 8º | AP9: 9º | AQ9: Indicador de Rendimento (P) | AR9: 6º a 9º ano | AS9: 6º | AT9: 7º | AU9: 8º | AV9: 9º | AW9: Indicador de Rendimento (P) | AX9: 6º a 9º ano | AY9: 6º | AZ9: 7º | BA9: 8º | BB9: 9º | BC9: Indicador de Rendimento (P) | BD9: 6º a 9º ano | BE9: 6º | BF9: 7º | BG9: 8º | BH9: 9º | BI9: Indicador de Rendimento (P) | BJ9: 6º a 9º ano | BK9: 6º | BL9: 7º | BM9: 8º | BN9: 9º | BO9: Indicador de Rendimento (P) | DD9: 2007 | DE9: 2009 | DF9: 2011 | DG9: 2013 | DH9: 2015 | DI9: 2017 | DJ9: 2019 | DK9: 2021
A10: SG_UF | B10: CO_MUNICIPIO | C10: NO_MUNICIPIO | E10: ID_ESCOLA | F10: NO_ESCOLA | G10: REDE | H10: VL_APROVACAO_2005_SI_4 | I10: VL_APROVACAO_2005_1 | J10: VL_APROVACAO_2005_2 | K10: VL_APROVACAO_2005_3 | L10: VL_APROVACAO_2005_4 | M10: VL_INDICADOR_REND_2005 | N10: VL_APROVACAO_2007_SI_4 | O10: VL_APROVACAO_2007_1 | P10: VL_APROVACAO_2007_2 | Q10: VL_APROVACAO_2007_3 | R10: VL_APROVACAO_2007_4 | S10: VL_INDICADOR_REND_2007 | T10: VL_APROVACAO_2009_SI_4 | U10: VL_APROVACAO_2009_1 | V10: VL_APROVACAO_2009_2 | W10: VL_APROVACAO_2009_3 | X10: VL_APROVACAO_2009_4 | Y10: VL_INDICADOR_REND_2009 | Z10: VL_APROVACAO_2011_SI_4 | AA10: VL_APROVACAO_2011_1 | AB10: VL_APROVACAO_2011_2 | AC10: VL_APROVACAO_2011_3 | AD10: VL_APROVACAO_2011_4 | AE10: VL_INDICADOR_REND_2011 | AF10: VL_APROVACAO_2013_SI_4 | AG10: VL_APROVACAO_2013_1 | AH10: VL_APROVACAO_2013_2 | AI10: VL_APROVACAO_2013_3 | AJ10: VL_APROVACAO_2013_4 | AK10: VL_INDICADOR_REND_2013 | AL10: VL_APROVACAO_2015_SI_4 | AM10: VL_APROVACAO_2015_1 | AN10: VL_APROVACAO_2015_2 | AO10: VL_APROVACAO_2015_3 | AP10: VL_APROVACAO_2015_4 | AQ10: VL_INDICADOR_REND_2015 | AR10: VL_APROVACAO_2017_SI_4 | AS10: VL_APROVACAO_2017_1 | AT10: VL_APROVACAO_2017_2 | AU10: VL_APROVACAO_2017_3 | AV10: VL_APROVACAO_2017_4 | AW10: VL_INDICADOR_REND_2017 | AX10: VL_APROVACAO_2019_SI_4 | AY10: VL_APROVACAO_2019_1 | AZ10: VL_APROVACAO_2019_2 | BA10: VL_APROVACAO_2019_3 | BB10: VL_APROVACAO_2019_4 | BC10: VL_INDICADOR_REND_2019 | BD10: VL_APROVACAO_2021_SI_4 | BE10: VL_APROVACAO_2021_1 | BF10: VL_APROVACAO_2021_2 | BG10: VL_APROVACAO_2021_3 | BH10: VL_APROVACAO_2021_4 | BI10: VL_INDICADOR_REND_2021 | BJ10: VL_APROVACAO_2023_SI_4 | BK10: VL_APROVACAO_2023_1 | BL10: VL_APROVACAO_2023_2 | BM10: VL_APROVACAO_2023_3 | BN10: VL_APROVACAO_2023_4 | BO10: VL_INDICADOR_REND_2023 | BP10: VL_NOTA_MATEMATICA_2005 | BQ10: VL_NOTA_PORTUGUES_2005 | BR10: VL_NOTA_MEDIA_2005 | BS10: VL_NOTA_MATEMATICA_2007 | BT10: VL_NOTA_PORTUGUES_2007 | BU10: VL_NOTA_MEDIA_2007 | BV10: VL_NOTA_MATEMATICA_2009 | BW10: VL_NOTA_PORTUGUES_2009 | BX10: VL_NOTA_MEDIA_2009 | BY10: VL_NOTA_MATEMATICA_2011 | BZ10: VL_NOTA_PORTUGUES_2011 | CA10: VL_NOTA_MEDIA_2011 | CB10: VL_NOTA_MATEMATICA_2013 | CC10: VL_NOTA_PORTUGUES_2013 | CD10: VL_NOTA_MEDIA_2013 | CE10: VL_NOTA_MATEMATICA_2015 | CF10: VL_NOTA_PORTUGUES_2015 | CG10: VL_NOTA_MEDIA_2015 | CH10: VL_NOTA_MATEMATICA_2017 | CI10: VL_NOTA_PORTUGUES_2017 | CJ10: VL_NOTA_MEDIA_2017 | CK10: VL_NOTA_MATEMATICA_2019 | CL10: VL_NOTA_PORTUGUES_2019 | CM10: VL_NOTA_MEDIA_2019 | CN10: VL_NOTA_MATEMATICA_2021 | CO10: VL_NOTA_PORTUGUES_2021 | CP10: VL_NOTA_MEDIA_2021 | CQ10: VL_NOTA_MATEMATICA_2023 | CR10: VL_NOTA_PORTUGUES_2023 | CS10: VL_NOTA_MEDIA_2023 | CT10: VL_OBSERVADO_2005 | CU10: VL_OBSERVADO_2007 | CV10: VL_OBSERVADO_2009 | CW10: VL_OBSERVADO_2011 | CX10: VL_OBSERVADO_2013 | CY10: VL_OBSERVADO_2015 | CZ10: VL_OBSERVADO_2017 | DA10: VL_OBSERVADO_2019 | DB10: VL_OBSERVADO_2021 | DC10: VL_OBSERVADO_2023 | DD10: VL_PROJECAO_2007 | DE10: VL_PROJECAO_2009 | DF10: VL_PROJECAO_2011 | DG10: VL_PROJECAO_2013 | DH10: VL_PROJECAO_2015 | DI10: VL_PROJECAO_2017 | DJ10: VL_PROJECAO_2019 | DK10: VL_PROJECAO_2021
A11: MG | B11: 3100906 | C11: Águas Formosas | D11: =VLOOKUP(B11,Planilha1!$A:$B,2,0) -> Vale do Mucuri | E11: 31312169 | F11: ESCOLA MUNICIPAL SEBASTIAO LIMA FILHO | G11: Municipal | H11: - | I11: - | J11: - | K11: - | L11: - | M11: - | N11: - | O11: - | P11: - | Q11: - | R11: - | S11: - | T11: 81.4 | U11: 59.3 | V11: 95.6 | W11: 88.5 | X11: 87 | Y11: 0.798127 | Z11: 89.3 | AA11: 71.7 | AB11: 92.3 | AC11: 97.1 | AD11: 100 | AE11: 0.887313 | AF11: 94.9 | AG11: 97.8 | AH11: 92.3 | AI11: 91.9 | AJ11: 100 | AK11: 0.95373 | AL11: 87.1 | AM11: 77.8 | AN11: 96.1 | AO11: 76.7 | AP11: 95 | AQ11: 0.854273 | AR11: 88.4 | AS11: 72.7 | AT11: 93.3 | AU11: 100 | AV11: 88.2 | AW11: 0.87315 | AX11: 93 | AY11: 93.9 | AZ11: 93.9 | BA11: 82.6 | BB11: 100 | BC11: 0.921536 | BD11: - | BE11: - | BF11: - | BG11: - | BH11: - | BI11: - | BJ11: 95.1 | BK11: 89.5 | BL11: 100 | BM11: 90.5 | BN11: 100 | BO11: 0.947353 | BP11: - | BQ11: - | BR11: - | BS11: - | BT11: - | BU11: - | BV11: 231.36 | BW11: 215.58 | BX11: 4.115667 | BY11: 210.25 | BZ11: 209.08 | CA11: 3.6555 | CB11: 237.15 | CC11: 226.31 | CD11: 4.391 | CE11: 237,53 | CF11: 233,65 | CG11: 4.519667 | CH11: 231.5 | CI11: 248.51 | CJ11: 4.666833 | CK11: 241.49 | CL11: 243.02 | CM11: 4.741833 | CN11: - | CO11: - | CP11: - | CQ11: ND | CR11: ND | CS11: - | CT11: - | CU11: - | CV11: 3.3 | CW11: 3.2 | CX11: 4.2 | CY11: 3.9 | CZ11: 4.1 | DA11: 4.4 | DB11: - | DC11: - | DD11: - | DE11: - | DF11: 3.4 | DG11: 3.7 | DH11: 4 | DI11: 4.3 | DJ11: 4.6 | DK11: 4.8
A12: MG | B12: 3104700 | C12: Ataléia | D12: =VLOOKUP(B12,Planilha1!$A:$B,2,0) -> Vale do Mucuri | E12: 31213080 | F12: EM DUQUE DE CAXIAS | G12: Municipal | H12: - | I12: - | J12: - | K12: - | L12: - | M12: - | N12: - | O12: - | P12: - | Q12: - | R12: - | S12: - | T12: - | U12: - | V12: - | W12: - | X12: - | Y12: - | Z12: - | AA12: - | AB12: - | AC12: - | AD12: - | AE12: - | AF12: - | AG12: - | AH12: - | AI12: - | AJ12: - | AK12: - | AL12: - | AM12: - | AN12: - | AO12: - | AP12: - | AQ12: - | AR12: 87.8 | AS12: 76.9 | AT12: 85.7 | AU12: 89.5 | AV12: 100 | AW12: 0.872492 | AX12: - | AY12: - | AZ12: - | BA12: - | BB12: - | BC12: - | BD12: 100 | BE12: 100 | BF12: 100 | BG12: 100 | BH12: 100 | BI12: 1 | BJ12: 97.8 | BK12: 100 | BL12: 100 | BM12: 90 | BN12: 100 | BO12: 0.972973 | BP12: - | BQ12: - | BR12: - | BS12: - | BT12: - | BU12: - | BV12: - | BW12: - | BX12: - | BY12: - | BZ12: - | CA12: - | CB12: - | CC12: - | CD12: - | CE12: - | CF12: - | CG12: - | CH12: 241.36 | CI12: 240.31 | CJ12: 4.6945 | CK12: - | CL12: - | CM12: - | CN12: 232.05 | CO12: 231.75 | CP12: 4.396667 | CQ12: 212.43 | CR12: 214.86 | CS12: 3.788167 | CT12: - | CU12: - | CV12: - | CW12: - | CX12: - | CY12: - | CZ12: 4.1 | DA12: - | DB12: 4.4 | DC12: 3.7 | DD12: - | DE12: - | DF12: - | DG12: - | DH12: - | DI12: - | DJ12: 4.3 | DK12: 4.6
A13: MG | B13: 3106606 | C13: Bertópolis | D13: =VLOOKUP(B13,Planilha1!$A:$B,2,0) -> Vale do Mucuri | E13: 31239461 | F13: EM PROF WALDEMAR MENDES DE CASTRO | G13: Municipal | H13: - | I13: - | J13: - | K13: - | L13: - | M13: - | N13: 79.6 | O13: 78.4 | P13: 68.1 | Q13: 85.9 | R13: 86.5 | S13: 0.789866 | T13: 85.4 | U13: 80.5 | V13: 88.9 | W13: 85 | X13: 87.8 | Y13: 0.854241 | Z13: - | AA13: - | AB13: - | AC13: - | AD13: - | AE13: - | AF13: - | AG13: - | AH13: - | AI13: - | AJ13: - | AK13: - | AL13: - | AM13: - | AN13: - | AO13: - | AP13: - | AQ13: - | AR13: - | AS13: - | AT13: - | AU13: - | AV13: - | AW13: - | AX13: - | AY13: - | AZ13: - | BA13: - | BB13: - | BC13: - | BD13: - | BE13: - | BF13: - | BG13: - | BH13: - | BI13: - | BJ13: - | BK13: - | BL13: - | BM13: - | BN13: - | BO13: - | BP13: - | BQ13: - | BR13: - | BS13: 276.27 | BT13: 251.56 | BU13: 5.463833 | BV13: 240.95 | BW13: 237.93 | BX13: 4.648 | BY13: - | BZ13: - | CA13: - | CB13: - | CC13: - | CD13: - | CE13: - | CF13: - | CG13: - | CH13: - | CI13: - | CJ13: - | CK13: - | CL13: - | CM13: - | CN13: - | CO13: - | CP13: - | CQ13: - | CR13: - | CS13: - | CT13: - | CU13: 4.3 | CV13: 4 | CW13: - | CX13: - | CY13: - | CZ13: - | DA13: - | DB13: - | DC13: - | DD13: - | DE13: 4.4 | DF13: 4.6 | DG13: 4.9 | DH13: 5.3 | DI13: 5.5 | DJ13: 5.7 | DK13: 6
A14: MG | B14: 3113701 | C14: Carlos Chagas | D14: =VLOOKUP(B14,Planilha1!$A:$B,2,0) -> Vale do Mucuri | E14: 31146587 | F14: ESCOLA MUNICIPAL DOUTOR MANOEL ESTEVES OTONI | G14: Municipal | H14: 77.2 | I14: 77.7 | J14: 77.2 | K14: 66.7 | L14: 97.1 | M14: 0.782556 | N14: 88.4 | O14: 85.7 | P14: 87.5 | Q14: 98.3 | R14: 82.6 | S14: 0.88151 | T14: 86.1 | U14: 74.4 | V14: 92.7 | W14: 97.8 | X14: 90 | Y14: 0.877878 | Z14: 93.6 | AA14: 92.9 | AB14: 90.6 | AC14: 95.6 | AD14: 97.1 | AE14: 0.939834 | AF14: 91.2 | AG14: 100 | AH14: 94.1 | AI14: 83.6 | AJ14: 92.7 | AK14: 0.922165 | AL14: 92.6 | AM14: 87.7 | AN14: 96.4 | AO14: 93.2 | AP14: 94.7 | AQ14: 0.928824 | AR14: 77.2 | AS14: 76.5 | AT14: 76.7 | AU14: 71.4 | AV14: 84.8 | AW14: 0.770598 | AX14: 84 | AY14: 71.9 | AZ14: 89.2 | BA14: 90.9 | BB14: 95.5 | BC14: 0.85853 | BD14: 93.6 | BE14: 88 | BF14: 92.9 | BG14: 95.2 | BH14: 98.2 | BI14: 0.934243 | BJ14: 86.7 | BK14: 76.5 | BL14: 93 | BM14: 87.9 | BN14: 94.1 | BO14: 0.872826 | BP14: 238.43 | BQ14: 221.78 | BR14: 4.336782 | BS14: 242.95 | BT14: 247.1 | BU14: 4.834167 | BV14: 251.44 | BW14: 248.82 | BX14: 5.004333 | BY14: 231.91 | BZ14: 227.24 | CA14: 4.319167 | CB14: 231.17 | CC14: 242.62 | CD14: 4.563167 | CE14: 243,71 | CF14: 240,19 | CG14: 4.731667 | CH14: 241.71 | CI14: 255.16 | CJ14: 4.947833 | CK14: ND | CL14: ND | CM14: - | CN14: 246.17 | CO14: 247.34 | CP14: 4.891833 | CQ14: 236.82 | CR14: 229.8 | CS14: 4.443667 | CT14: 3.4 | CU14: 4.3 | CV14: 4.4 | CW14: 4.1 | CX14: 4.2 | CY14: 4.4 | CZ14: 3.8 | DA14: - | DB14: 4.6 | DC14: 3.9 | DD14: 3.4 | DE14: 3.6 | DF14: 3.8 | DG14: 4.3 | DH14: 4.6 | DI14: 4.9 | DJ14: 5.1 | DK14: 5.4
A15: MG | B15: 3113701 | C15: Carlos Chagas | D15: =VLOOKUP(B15,Planilha1!$A:$B,2,0) -> Vale do Mucuri | E15: 31151025 | F15: ESCOLA MUNICIPAL OSCAR JOAO KRETLI | G15: Municipal | H15: - | I15: - | J15: - | K15: - | L15: - | M15: - | N15: - | O15: - | P15: - | Q15: - | R15: - | S15: - | T15: 94 | U15: 95.7 | V15: 96.7 | W15: 94.9 | X15: 90.5 | Y15: 0.943892 | Z15: 99.1 | AA15: 96.2 | AB15: 100 | AC15: 100 | AD15: 100 | AE15: 0.990221 | AF15: 91.9 | AG15: 92 | AH15: 83.3 | AI15: 95.2 | AJ15: 100 | AK15: 0.922114 | AL15: 98.7 | AM15: 100 | AN15: 100 | AO15: 100 | AP15: 94.7 | AQ15: 0.986202 | AR15: 95.7 | AS15: 94.4 | AT15: 100 | AU15: 87.5 | AV15: 100 | AW15: 0.951887 | AX15: 85.2 | AY15: 84.2 | AZ15: 83.3 | BA15: 79.2 | BB15: 95.2 | BC15: 0.850851 | BD15: 93.7 | BE15: 93.8 | BF15: 94.1 | BG15: 92.9 | BH15: 93.8 | BI15: 0.936478 | BJ15: 95.5 | BK15: 95.2 | BL15: 95.2 | BM15: 100 | BN15: 93.3 | BO15: 0.958623 | BP15: - | BQ15: - | BR15: - | BS15: - | BT15: - | BU15: - | BV15: 225.63 | BW15: 228.13 | BX15: 4.229333 | BY15: 255.88 | BZ15: 243.7 | CA15: 4.993 | CB15: - | CC15: - | CD15: - | CE15: 256,05 | CF15: 262,44 | CG15: 5.308167 | CH15: 258.14 | CI15: 261.88 | CJ15: 5.333667 | CK15: 277.83 | CL15: 265.69 | CM15: 5.725333 | CN15: 236.77 | CO15: 231.43 | CP15: 4.47 | CQ15: 248.09 | CR15: 243.31 | CS15: 4.856667 | CT15: - | CU15: - | CV15: 4 | CW15: 4.9 | CX15: - | CY15: 5.2 | CZ15: 5.1 | DA15: 4.9 | DB15: 4.2 | DC15: 4.7 | DD15: - | DE15: - | DF15: 4.1 | DG15: 4.4 | DH15: 4.7 | DI15: 5 | DJ15: 5.3 | DK15: 5.5
A16: MG | B16: 3115458 | C16: Catuji | D16: =VLOOKUP(B16,Planilha1!$A:$B,2,0) -> Vale do Mucuri | E16: 31326771 | F16: EM DE ENSINO FUNDAMENTAL DE CATUJI | G16: Municipal | H16: - | I16: - | J16: - | K16: - | L16: - | M16: - | N16: - | O16: - | P16: - | Q16: - | R16: - | S16: - | T16: 52.5 | U16: 45.8 | V16: 33.3 | W16: 66.7 | X16: 62.5 | Y16: 0.482762 | Z16: 54.7 | AA16: 20 | AB16: 28.6 | AC16: 71.4 | AD16: 82.6 | AE16: 0.36011 | AF16: - | AG16: - | AH16: - | AI16: - | AJ16: - | AK16: - | AL16: - | AM16: - | AN16: - | AO16: - | AP16: - | AQ16: - | AR16: - | AS16: - | AT16: - | AU16: - | AV16: - | AW16: - | AX16: - | AY16: - | AZ16: - | BA16: - | BB16: - | BC16: - | BD16: - | BE16: - | BF16: - | BG16: - | BH16: - | BI16: - | BJ16: - | BK16: - | BL16: - | BM16: - | BN16: - | BO16: - | BP16: - | BQ16: - | BR16: - | BS16: - | BT16: - | BU16: - | BV16: 223.32 | BW16: 234.87 | BX16: 4.303167 | BY16: 236.65 | BZ16: 238.7 | CA16: 4.589167 | CB16: - | CC16: - | CD16: - | CE16: - | CF16: - | CG16: - | CH16: - | CI16: - | CJ16: - | CK16: - | CL16: - | CM16: - | CN16: - | CO16: - | CP16: - | CQ16: - | CR16: - | CS16: - | CT16: - | CU16: - | CV16: 2.1 | CW16: 1.7 | CX16: - | CY16: - | CZ16: - | DA16: - | DB16: - | DC16: - | DD16: - | DE16: - | DF16: 2.7 | DG16: 3.1 | DH16: 3.5 | DI16: 3.8 | DJ16: 4.1 | DK16: 4.3
A17: MG | B17: 3120151 | C17: Crisólita | D17: =VLOOKUP(B17,Planilha1!$A:$B,2,0) -> Vale do Mucuri | E17: 31145971 | F17: ESCOLA MUNICIPAL DA FAZENDA AVENIDA | G17: Municipal | H17: 76.6 | I17: 68.9 | J17: 79.2 | K17: 76.2 | L17: 86.8 | M17: 0.772437 | N17: 86.4 | O17: 74.7 | P17: 88.9 | Q17: 93.2 | R17: 93.3 | S17: 0.867995 | T17: 74.2 | U17: 51.5 | V17: 87.5 | W17: 83.6 | X17: 79.7 | Y17: 0.722611 | Z17: 74.5 | AA17: 62.5 | AB17: 60.8 | AC17: 96.7 | AD17: 89.1 | AE17: 0.740577 | AF17: 86.4 | AG17: 70.4 | AH17: 94 | AI17: 96.3 | AJ17: 89.7 | AK17: 0.862528 | AL17: 87.9 | AM17: 77.2 | AN17: 80 | AO17: 97.4 | AP17: 95.9 | AQ17: 0.86678 | AR17: 95.3 | AS17: 100 | AT17: 94.7 | AU17: 100 | AV17: 88.9 | AW17: 0.956749 | AX17: 80 | AY17: 70 | AZ17: 76.9 | BA17: 91.7 | BB17: 83.8 | BC17: 0.797959 | BD17: 94.6 | BE17: 100 | BF17: 93.9 | BG17: 89.3 | BH17: 93.9 | BI17: 0.941233 | BJ17: 95.8 | BK17: 94.6 | BL17: 93.8 | BM17: 97.1 | BN17: 96.9 | BO17: 0.955786 | BP17: 215.2 | BQ17: 200.34 | BR17: 3.592486 | BS17: 215.71 | BT17: 208.74 | BU17: 3.740833 | BV17: 230.86 | BW17: 229.6 | BX17: 4.341 | BY17: 231.16 | BZ17: 227.63 | CA17: 4.313167 | CB17: 237.26 | CC17: 237.12 | CD17: 4.573 | CE17: 242,42 | CF17: 233,71 | CG17: 4.602167 | CH17: 228.82 | CI17: 240.07 | CJ17: 4.4815 | CK17: 232.96 | CL17: 226.05 | CM17: 4.316833 | CN17: 226.56 | CO17: 229.62 | CP17: 4.269667 | CQ17: 221.47 | CR17: 230.89 | CS17: 4.206 | CT17: 2.8 | CU17: 3.2 | CV17: 3.1 | CW17: 3.2 | CX17: 3.9 | CY17: 4 | CZ17: 4.3 | DA17: 3.4 | DB17: 4 | DC17: 4 | DD17: 2.8 | DE17: 2.9 | DF17: 3.2 | DG17: 3.6 | DH17: 4 | DI17: 4.3 | DJ17: 4.5 | DK17: 4.8
A18: MG | B18: 3120151 | C18: Crisólita | D18: =VLOOKUP(B18,Planilha1!$A:$B,2,0) -> Vale do Mucuri | E18: 31349704 | F18: ESCOLA MUNICIPAL JOAO GONCALVES DA ROCHA | G18: Municipal | H18: - | I18: - | J18: - | K18: - | L18: - | M18: - | N18: - | O18: - | P18: - | Q18: - | R18: - | S18: - | T18: - | U18: - | V18: - | W18: - | X18: - | Y18: - | Z18: - | AA18: - | AB18: - | AC18: - | AD18: - | AE18: - | AF18: 92.6 | AG18: 97.1 | AH18: 86.7 | AI18: 88 | AJ18: 95 | AK18: 0.914858 | AL18: - | AM18: - | AN18: - | AO18: - | AP18: - | AQ18: - | AR18: - | AS18: - | AT18: - | AU18: - | AV18: - | AW18: - | AX18: - | AY18: - | AZ18: - | BA18: - | BB18: - | BC18: - | BD18: - | BE18: - | BF18: - | BG18: - | BH18: - | BI18: - | BJ18: - | BK18: - | BL18: - | BM18: - | BN18: - | BO18: - | BP18: - | BQ18: - | BR18: - | BS18: - | BT18: - | BU18: - | BV18: - | BW18: - | BX18: - | BY18: - | BZ18: - | CA18: - | CB18: 230.61 | CC18: 233.18 | CD18: 4.3965 | CE18: - | CF18: - | CG18: - | CH18: - | CI18: - | CJ18: - | CK18: - | CL18: - | CM18: - | CN18: - | CO18: - | CP18: - | CQ18: - | CR18: - | CS18: - | CT18: - | CU18: - | CV18: - | CW18: - | CX18: 4 | CY18: - | CZ18: - | DA18: - | DB18: - | DC18: - | DD18: - | DE18: - | DF18: - | DG18: - | DH18: 4.3 | DI18: 4.5 | DJ18: 4.8 | DK18: 5
A19: MG | B19: 3126752 | C19: Franciscópolis | D19: =VLOOKUP(B19,Planilha1!$A:$B,2,0) -> Vale do Mucuri | E19: 31154253 | F19: EM VICENTE MACEDO | G19: Municipal | H19: 44.7 | I19: 37.5 | J19: 26.9 | K19: 58.6 | L19: 50 | M19: 0.396408 | N19: 46.2 | O19: 45.5 | P19: 46.2 | Q19: 20 | R19: 61.1 | S19: 0.363671 | T19: 71.9 | U19: 70 | V19: - | W19: 72.7 | X19: - | Y19: 0.713245 | Z19: - | AA19: - | AB19: - | AC19: - | AD19: - | AE19: - | AF19: - | AG19: - | AH19: - | AI19: - | AJ19: - | AK19: - | AL19: - | AM19: - | AN19: - | AO19: - | AP19: - | AQ19: - | AR19: - | AS19: - | AT19: - | AU19: - | AV19: - | AW19: - | AX19: - | AY19: - | AZ19: - | BA19: - | BB19: - | BC19: - | BD19: - | BE19: - | BF19: - | BG19: - | BH19: - | BI19: - | BJ19: - | BK19: - | BL19: - | BM19: - | BN19: - | BO19: - | BP19: 218.64 | BQ19: 193.7 | BR19: 3.538929 | BS19: 251.32 | BT19: 242.04 | BU19: 4.889333 | BV19: - | BW19: - | BX19: - | BY19: - | BZ19: - | CA19: - | CB19: - | CC19: - | CD19: - | CE19: - | CF19: - | CG19: - | CH19: - | CI19: - | CJ19: - | CK19: - | CL19: - | CM19: - | CN19: - | CO19: - | CP19: - | CQ19: - | CR19: - | CS19: - | CT19: 1.4 | CU19: 1.8 | CV19: - | CW19: - | CX19: - | CY19: - | CZ19: - | DA19: - | DB19: - | DC19: - | DD19: 1.5 | DE19: 1.9 | DF19: 2.4 | DG19: 3 | DH19: 3.5 | DI19: 3.7 | DJ19: 4 | DK19: 4.3
A20: MG | B20: 3126802 | C20: Frei Gaspar | D20: =VLOOKUP(B20,Planilha1!$A:$B,2,0) -> Vale do Mucuri | E20: 31151556 | F20: EM ESTEVAO MONTEIRO | G20: Municipal | H20: - | I20: - | J20: - | K20: - | L20: - | M20: - | N20: - | O20: - | P20: - | Q20: - | R20: - | S20: - | T20: - | U20: - | V20: - | W20: - | X20: - | Y20: - | Z20: - | AA20: - | AB20: - | AC20: - | AD20: - | AE20: - | AF20: - | AG20: - | AH20: - | AI20: - | AJ20: - | AK20: - | AL20: - | AM20: - | AN20: - | AO20: - | AP20: - | AQ20: - | AR20: 88.2 | AS20: 70 | AT20: 92.3 | AU20: 86.7 | AV20: 100 | AW20: 0.857376 | AX20: 91.5 | AY20: 83.3 | AZ20: 95.8 | BA20: 90 | BB20: 92.3 | BC20: 0.901133 | BD20: - | BE20: - | BF20: - | BG20: - | BH20: - | BI20: - | BJ20: 84.7 | BK20: 71.4 | BL20: 88.2 | BM20: 82.4 | BN20: 100 | BO20: 0.842471 | BP20: - | BQ20: - | BR20: - | BS20: - | BT20: - | BU20: - | BV20: - | BW20: - | BX20: - | BY20: - | BZ20: - | CA20: - | CB20: - | CC20: - | CD20: - | CE20: - | CF20: - | CG20: - | CH20: 257 | CI20: 253.13 | CJ20: 5.168833 | CK20: 220.23 | CL20: 231.86 | CM20: 4.2015 | CN20: - | CO20: - | CP20: - | CQ20: 251.4 | CR20: 248.77 | CS20: 5.002833 | CT20: - | CU20: - | CV20: - | CW20: - | CX20: - | CY20: - | CZ20: 4.4 | DA20: 3.8 | DB20: - | DC20: 4.2 | DD20: - | DE20: - | DF20: - | DG20: - | DH20: - | DI20: - | DJ20: 4.7 | DK20: 4.9
A21: MG | B21: 3126802 | C21: Frei Gaspar | D21: =VLOOKUP(B21,Planilha1!$A:$B,2,0) -> Vale do Mucuri | E21: 31151599 | F21: EM ZELITA CARLOS DE OLIVEIRA | G21: Municipal | H21: - | I21: - | J21: - | K21: - | L21: - | M21: - | N21: - | O21: - | P21: - | Q21: - | R21: - | S21: - | T21: 67.3 | U21: 49.2 | V21: 64.3 | W21: 92.9 | X21: 85.7 | Y21: 0.685987 | Z21: 80.3 | AA21: 71.2 | AB21: 75.6 | AC21: 95.6 | AD21: 86.2 | AE21: 0.810806 | AF21: 96.4 | AG21: 93.6 | AH21: 95.5 | AI21: 100 | AJ21: 100 | AK21: 0.971936 | AL21: 91.1 | AM21: 73.3 | AN21: 92.3 | AO21: 91.8 | AP21: 100 | AQ21: 0.881639 | AR21: 78.8 | AS21: 69.1 | AT21: 74.4 | AU21: 84.4 | AV21: 100 | AW21: 0.803843 | AX21: 68.8 | AY21: 58.8 | AZ21: 68.4 | BA21: 76.5 | BB21: 81 | BC21: 0.70121 | BD21: 96.2 | BE21: 96.2 | BF21: 94.9 | BG21: 96.6 | BH21: 96.9 | BI21: 0.961439 | BJ21: 80.2 | BK21: 84.2 | BL21: 77.1 | BM21: 68.8 | BN21: 87.1 | BO21: 0.786433 | BP21: - | BQ21: - | BR21: - | BS21: - | BT21: - | BU21: - | BV21: 232.72 | BW21: 236.04 | BX21: 4.479333 | BY21: 237.02 | BZ21: 238.33 | CA21: 4.589167 | CB21: 225.85 | CC21: 223.96 | CD21: 4.1635 | CE21: 234,02 | CF21: 230,38 | CG21: 4.406667 | CH21: ND | CI21: ND | CJ21: - | CK21: ND | CL21: ND | CM21: - | CN21: ND | CO21: ND | CP21: - | CQ21: 220.35 | CR21: 224.38 | CS21: 4.078833 | CT21: - | CU21: - | CV21: 3.1 | CW21: 3.7 | CX21: 4 | CY21: 3.9 | CZ21: - | DA21: - | DB21: - | DC21: 3.2 | DD21: - | DE21: - | DF21: 3.2 | DG21: 3.5 | DH21: 3.8 | DI21: 4.1 | DJ21: 4.4 | DK21: 4.6
A22: MG | B22: 3127057 | C22: Fronteira dos Vales | D22: =VLOOKUP(B22,Planilha1!$A:$B,2,0) -> Vale do Mucuri | E22: 31146722 | F22: EM DE JOAQUIM DIAS ALMEIDA | G22: Municipal | H22: - | I22: - | J22: - | K22: - | L22: - | M22: - | N22: - | O22: - | P22: - | Q22: - | R22: - | S22: - | T22: 72.2 | U22: 57.5 | V22: 82.8 | W22: 94.1 | X22: 69 | Y22: 0.732757 | Z22: 69.1 | AA22: 45.7 | AB22: 60.9 | AC22: 100 | AD22: 95 | AE22: 0.679942 | AF22: 86.7 | AG22: 66.7 | AH22: 95.8 | AI22: 100 | AJ22: 100 | AK22: 0.880458 | AL22: - | AM22: - | AN22: - | AO22: - | AP22: - | AQ22: - | AR22: 94.7 | AS22: 96.2 | AT22: 88.9 | AU22: 100 | AV22: 94.1 | AW22: 0.946284 | AX22: 84 | AY22: 79.2 | AZ22: 80 | BA22: 89.7 | BB22: 85.7 | BC22: 0.834322 | BD22: - | BE22: - | BF22: - | BG22: - | BH22: - | BI22: - | BJ22: 100 | BK22: 100 | BL22: 100 | BM22: 100 | BN22: 100 | BO22: 1 | BP22: - | BQ22: - | BR22: - | BS22: - | BT22: - | BU22: - | BV22: 214.23 | BW22: 213.85 | BX22: 3.801333 | BY22: 248.07 | BZ22: 242.67 | CA22: 4.845667 | CB22: - | CC22: - | CD22: - | CE22: - | CF22: - | CG22: - | CH22: ND | CI22: ND | CJ22: - | CK22: ND | CL22: ND | CM22: - | CN22: - | CO22: - | CP22: - | CQ22: 213.35 | CR22: 207.76 | CS22: 3.685167 | CT22: - | CU22: - | CV22: 2.8 | CW22: 3.3 | CX22: - | CY22: - | CZ22: - | DA22: - | DB22: - | DC22: 3.7 | DD22: - | DE22: - | DF22: 2.9 | DG22: 3.2 | DH22: 3.5 | DI22: 3.8 | DJ22: 4.1 | DK22: 4.3
A23: MG | B23: 3132305 | C23: Itaipé | D23: =VLOOKUP(B23,Planilha1!$A:$B,2,0) -> Vale do Mucuri | E23: 31338478 | F23: EM MARIA DE FATIMA BATISTA MATIAS | G23: Municipal | H23: - | I23: - | J23: - | K23: - | L23: - | M23: - | N23: - | O23: - | P23: - | Q23: - | R23: - | S23: - | T23: - | U23: - | V23: - | W23: - | X23: - | Y23: - | Z23: 73.2 | AA23: 61 | AB23: 80 | AC23: 88 | AD23: 76.8 | AE23: 0.75078 | AF23: 87.8 | AG23: 82.6 | AH23: 89.7 | AI23: 93.4 | AJ23: 89.4 | AK23: 0.885992 | AL23: 73.6 | AM23: 61.8 | AN23: 80.8 | AO23: 84.3 | AP23: 87 | AQ23: 0.770503 | AR23: 61.8 | AS23: 44.3 | AT23: 64.7 | AU23: 79.4 | AV23: 86.4 | AW23: 0.643109 | AX23: 44.8 | AY23: 35.1 | AZ23: 38.3 | BA23: 56.9 | BB23: 74.5 | BC23: 0.467305 | BD23: 99.3 | BE23: 98.9 | BF23: 100 | BG23: 98.9 | BH23: 98.1 | BI23: 0.989704 | BJ23: 62.6 | BK23: 58.8 | BL23: 62.3 | BM23: 54.1 | BN23: 81.9 | BO23: 0.627427 | BP23: - | BQ23: - | BR23: - | BS23: - | BT23: - | BU23: - | BV23: - | BW23: - | BX23: - | BY23: 239.32 | BZ23: 241.52 | CA23: 4.680667 | CB23: 258.49 | CC23: 241.54 | CD23: 5.0005 | CE23: ND | CF23: ND | CG23: - | CH23: 253.71 | CI23: 254.01 | CJ23: 5.128667 | CK23: 230.96 | CL23: 249.7 | CM23: 4.677667 | CN23: ND | CO23: ND | CP23: - | CQ23: 227.73 | CR23: 226.19 | CS23: 4.232 | CT23: - | CU23: - | CV23: - | CW23: 3.5 | CX23: 4.4 | CY23: - | CZ23: 3.3 | DA23: 2.2 | DB23: - | DC23: 2.7 | DD23: - | DE23: - | DF23: - | DG23: 3.7 | DH23: 4 | DI23: 4.3 | DJ23: 4.5 | DK23: 4.8
A24: MG | B24: 3137007 | C24: Ladainha | D24: =VLOOKUP(B24,Planilha1!$A:$B,2,0) -> Vale do Mucuri | E24: 31153711 | F24: EM SEBASTIAO PEREIRA CAMPOS | G24: Municipal | H24: - | I24: - | J24: - | K24: - | L24: - | M24: - | N24: - | O24: - | P24: - | Q24: - | R24: - | S24: - | T24: 60.7 | U24: 54.3 | V24: 55 | W24: 63.6 | X24: 69.1 | Y24: 0.598864 | Z24: 66.2 | AA24: 67.5 | AB24: 81.3 | AC24: 58.7 | AD24: 60 | AE24: 0.657707 | AF24: 96.9 | AG24: 97 | AH24: 100 | AI24: 93.8 | AJ24: 94.7 | AK24: 0.963161 | AL24: 92.6 | AM24: 87.8 | AN24: 95.3 | AO24: 83.7 | AP24: 100 | AQ24: 0.912614 | AR24: 62.5 | AS24: 52 | AT24: 59.6 | AU24: 55.6 | AV24: 87.3 | AW24: 0.611157 | AX24: 70.7 | AY24: 51.5 | AZ24: 77 | BA24: 78.6 | BB24: 89.7 | BC24: 0.71079 | BD24: 95.5 | BE24: 100 | BF24: 90.2 | BG24: 95 | BH24: 98.3 | BI24: 0.957265 | BJ24: 75.2 | BK24: 59.3 | BL24: 84.2 | BM24: 69.7 | BN24: 89.5 | BO24: 0.737188 | BP24: - | BQ24: - | BR24: - | BS24: - | BT24: - | BU24: - | BV24: 216.93 | BW24: 214.13 | BX24: 3.851 | BY24: 220.38 | BZ24: 224.15 | CA24: 4.0755 | CB24: 231.65 | CC24: 225.92 | CD24: 4.292833 | CE24: 232,27 | CF24: 229,92 | CG24: 4.369833 | CH24: 235.95 | CI24: 243.45 | CJ24: 4.656667 | CK24: 226.78 | CL24: 218.63 | CM24: 4.090167 | CN24: ND | CO24: ND | CP24: - | CQ24: ND | CR24: ND | CS24: - | CT24: - | CU24: - | CV24: 2.3 | CW24: 2.7 | CX24: 4.1 | CY24: 4 | CZ24: 2.8 | DA24: 2.9 | DB24: - | DC24: - | DD24: - | DE24: - | DF24: 2.6 | DG24: 2.9 | DH24: 3.2 | DI24: 3.5 | DJ24: 3.7 | DK24: 4
A25: MG | B25: 3139201 | C25: Malacacheta | D25: =VLOOKUP(B25,Planilha1!$A:$B,2,0) -> Vale do Mucuri | E25: 31154059 | F25: EM MANOEL GOMES DE PAULA | G25: Municipal | H25: - | I25: - | J25: - | K25: - | L25: - | M25: - | N25: - | O25: - | P25: - | Q25: - | R25: - | S25: - | T25: - | U25: - | V25: - | W25: - | X25: - | Y25: - | Z25: - | AA25: - | AB25: - | AC25: - | AD25: - | AE25: - | AF25: - | AG25: - | AH25: - | AI25: - | AJ25: - | AK25: - | AL25: - | AM25: - | AN25: - | AO25: - | AP25: - | AQ25: - | AR25: 87.5 | AS25: 100 | AT25: 78.9 | AU25: 85.7 | AV25: 84.2 | AW25: 0.865438 | AX25: 79.2 | AY25: 85 | AZ25: 52.6 | BA25: 85 | BB25: 100 | BC25: 0.761313 | BD25: - | BE25: - | BF25: - | BG25: - | BH25: - | BI25: - | BJ25: - | BK25: - | BL25: - | BM25: - | BN25: - | BO25: - | BP25: - | BQ25: - | BR25: - | BS25: - | BT25: - | BU25: - | BV25: - | BW25: - | BX25: - | BY25: - | BZ25: - | CA25: - | CB25: - | CC25: - | CD25: - | CE25: - | CF25: - | CG25: - | CH25: 250.52 | CI25: 235.66 | CJ25: 4.769667 | CK25: 251.72 | CL25: 246.23 | CM25: 4.965833 | CN25: - | CO25: - | CP25: - | CQ25: - | CR25: - | CS25: - | CT25: - | CU25: - | CV25: - | CW25: - | CX25: - | CY25: - | CZ25: 4.1 | DA25: 3.8 | DB25: - | DC25: - | DD25: - | DE25: - | DF25: - | DG25: - | DH25: - | DI25: - | DJ25: 4.4 | DK25: 4.6
A26: MG | B26: 3139201 | C26: Malacacheta | D26: =VLOOKUP(B26,Planilha1!$A:$B,2,0) -> Vale do Mucuri | E26: 31222151 | F26: EM ARISTIDES GOMES PEREIRA | G26: Municipal | H26: - | I26: - | J26: - | K26: - | L26: - | M26: - | N26: - | O26: - | P26: - | Q26: - | R26: - | S26: - | T26: - | U26: - | V26: - | W26: - | X26: - | Y26: - | Z26: 90.3 | AA26: 91.7 | AB26: 80 | AC26: 100 | AD26: 94.4 | AE26: 0.909125 | AF26: 96.2 | AG26: 95.2 | AH26: 100 | AI26: 92.3 | AJ26: 94.1 | AK26: 0.953165 | AL26: 98.9 | AM26: 100 | AN26: 100 | AO26: 100 | AP26: 96.3 | AQ26: 0.990486 | AR26: 85.3 | AS26: 89.5 | AT26: 73.7 | AU26: 77.8 | AV26: 100 | AW26: 0.840421 | AX26: 98.2 | AY26: 100 | AZ26: 100 | BA26: 100 | BB26: 93.8 | BC26: 0.983744 | BD26: 98.1 | BE26: 100 | BF26: 100 | BG26: 100 | BH26: 93.3 | BI26: 0.982364 | BJ26: 95.2 | BK26: 100 | BL26: 100 | BM26: 93.8 | BN26: 90 | BO26: 0.957577 | BP26: - | BQ26: - | BR26: - | BS26: - | BT26: - | BU26: - | BV26: - | BW26: - | BX26: - | BY26: 237.42 | BZ26: 225.26 | CA26: 4.378 | CB26: - | CC26: - | CD26: - | CE26: 235,90 | CF26: 244,27 | CG26: 4.6695 | CH26: 246.61 | CI26: 239.02 | CJ26: 4.7605 | CK26: 239.72 | CL26: 226.62 | CM26: 4.439 | CN26: 244.45 | CO26: 232.18 | CP26: 4.6105 | CQ26: 228.72 | CR26: 221.13 | CS26: 4.164167 | CT26: - | CU26: - | CV26: - | CW26: 4 | CX26: - | CY26: 4.6 | CZ26: 4 | DA26: 4.4 | DB26: 4.5 | DC26: 4 | DD26: - | DE26: - | DF26: - | DG26: 4.2 | DH26: 4.5 | DI26: 4.7 | DJ26: 5 | DK26: 5.2
A27: MG | B27: 3139201 | C27: Malacacheta | D27: =VLOOKUP(B27,Planilha1!$A:$B,2,0) -> Vale do Mucuri | E27: 31299103 | F27: EM EVA RIBEIRO MENDES | G27: Municipal | H27: 38.5 | I27: 32.4 | J27: 32.6 | K27: 38.3 | L27: 44 | M27: 0.362398 | N27: 46.9 | O27: 22.2 | P27: 56.1 | Q27: 34.1 | R27: 57.9 | S27: 0.365407 | T27: 49.4 | U27: 35.3 | V27: 50 | W27: 23.8 | X27: 75.9 | Y27: 0.386396 | Z27: - | AA27: - | AB27: - | AC27: - | AD27: - | AE27: - | AF27: - | AG27: - | AH27: - | AI27: - | AJ27: - | AK27: - | AL27: - | AM27: - | AN27: - | AO27: - | AP27: - | AQ27: - | AR27: - | AS27: - | AT27: - | AU27: - | AV27: - | AW27: - | AX27: - | AY27: - | AZ27: - | BA27: - | BB27: - | BC27: - | BD27: - | BE27: - | BF27: - | BG27: - | BH27: - | BI27: - | BJ27: - | BK27: - | BL27: - | BM27: - | BN27: - | BO27: - | BP27: 225.9 | BQ27: 201.62 | BR27: 3.791989 | BS27: 237.74 | BT27: 226.36 | BU27: 4.401667 | BV27: 230.85 | BW27: 218.3 | BX27: 4.1525 | BY27: - | BZ27: - | CA27: - | CB27: - | CC27: - | CD27: - | CE27: - | CF27: - | CG27: - | CH27: - | CI27: - | CJ27: - | CK27: - | CL27: - | CM27: - | CN27: - | CO27: - | CP27: - | CQ27: - | CR27: - | CS27: - | CT27: 1.4 | CU27: 1.6 | CV27: 1.6 | CW27: - | CX27: - | CY27: - | CZ27: - | DA27: - | DB27: - | DC27: - | DD27: 1.5 | DE27: 1.9 | DF27: 2.5 | DG27: 3.1 | DH27: 3.6 | DI27: 3.9 | DJ27: 4.2 | DK27: 4.5
A28: MG | B28: 3144300 | C28: Nanuque | D28: =VLOOKUP(B28,Planilha1!$A:$B,2,0) -> Vale do Mucuri | E28: 31154717 | F28: EM SERAFIM MACHADO NAYA | G28: Municipal | H28: 69.8 | I28: 63.2 | J28: 74.4 | K28: 71.6 | L28: 78.2 | M28: 0.714058 | N28: 69.7 | O28: 63.9 | P28: 62.8 | Q28: 70.7 | R28: 90.8 | S28: 0.705088 | T28: 70.5 | U28: 57.1 | V28: 81 | W28: 77.8 | X28: 80.3 | Y28: 0.72509 | Z28: 67.5 | AA28: 48.7 | AB28: 71.4 | AC28: 79.2 | AD28: 92.9 | AE28: 0.690488 | AF28: 88.6 | AG28: 87.1 | AH28: 89.6 | AI28: 82.1 | AJ28: 100 | AK28: 0.892418 | AL28: 83.1 | AM28: 76.9 | AN28: 83.3 | AO28: 84.9 | AP28: 92.5 | AQ28: 0.84037 | AR28: 74.7 | AS28: 54.7 | AT28: 70.7 | AU28: 96.6 | AV28: 89.7 | AW28: 0.741757 | AX28: 69.5 | AY28: 60 | AZ28: 77.8 | BA28: 82.1 | BB28: 68.2 | BC28: 0.709683 | BD28: 90.7 | BE28: 93.2 | BF28: 86.1 | BG28: 94.1 | BH28: 88.5 | BI28: 0.903537 | BJ28: 92.9 | BK28: 87.9 | BL28: 91.7 | BM28: 96.3 | BN28: 100 | BO28: 0.937517 | BP28: 234.01 | BQ28: 215.54 | BR28: 4.159105 | BS28: 233.65 | BT28: 223.42 | BU28: 4.2845 | BV28: 237.38 | BW28: 230.73 | BX28: 4.4685 | BY28: 235.36 | BZ28: 237.48 | CA28: 4.547333 | CB28: 216.23 | CC28: 227.05 | CD28: 4.054667 | CE28: 236,53 | CF28: 247,26 | CG28: 4.729833 | CH28: 242.5 | CI28: 251.18 | CJ28: 4.894667 | CK28: ND | CL28: ND | CM28: - | CN28: 234.7 | CO28: 239.5 | CP28: 4.57 | CQ28: 218.89 | CR28: 230.11 | CS28: 4.15 | CT28: 3 | CU28: 3 | CV28: 3.2 | CW28: 3.1 | CX28: 3.6 | CY28: 4 | CZ28: 3.6 | DA28: - | DB28: 4.1 | DC28: 3.9 | DD28: 3 | DE28: 3.1 | DF28: 3.4 | DG28: 3.8 | DH28: 4.2 | DI28: 4.5 | DJ28: 4.7 | DK28: 5
A29: MG | B29: 3144300 | C29: Nanuque | D29: =VLOOKUP(B29,Planilha1!$A:$B,2,0) -> Vale do Mucuri | E29: 31154733 | F29: ESCOLA MUNICIPAL MIGUEL VIANA DE OLIVEIRA | G29: Municipal | H29: - | I29: - | J29: - | K29: - | L29: - | M29: - | N29: - | O29: - | P29: - | Q29: - | R29: - | S29: - | T29: 91.2 | U29: 96.6 | V29: 91.1 | W29: 86.7 | X29: 90.9 | Y29: 0.911909 | Z29: 91.8 | AA29: 93.3 | AB29: 90.5 | AC29: 87 | AD29: 95.7 | AE29: 0.915093 | AF29: 92 | AG29: 84 | AH29: 96.8 | AI29: 92.6 | AJ29: 94.1 | AK29: 0.91614 | AL29: 94.7 | AM29: 94.3 | AN29: 93.1 | AO29: 95 | AP29: 96.6 | AQ29: 0.947331 | AR29: 90.7 | AS29: 95.5 | AT29: 85.7 | AU29: 88.9 | AV29: 96 | AW29: 0.913136 | AX29: 96 | AY29: 93.3 | AZ29: 100 | BA29: 90 | BB29: 96.4 | BC29: 0.947807 | BD29: - | BE29: - | BF29: - | BG29: - | BH29: - | BI29: - | BJ29: - | BK29: - | BL29: - | BM29: - | BN29: - | BO29: - | BP29: - | BQ29: - | BR29: - | BS29: - | BT29: - | BU29: - | BV29: 242.13 | BW29: 245.62 | BX29: 4.795833 | BY29: 239.47 | BZ29: 236.46 | CA29: 4.598833 | CB29: - | CC29: - | CD29: - | CE29: 240,85 | CF29: 230,61 | CG29: 4.524333 | CH29: 249 | CI29: 246.95 | CJ29: 4.9325 | CK29: 234.34 | CL29: 232.9 | CM29: 4.454 | CN29: - | CO29: - | CP29: - | CQ29: - | CR29: - | CS29: - | CT29: - | CU29: - | CV29: 4.4 | CW29: 4.2 | CX29: - | CY29: 4.3 | CZ29: 4.5 | DA29: 4.2 | DB29: - | DC29: - | DD29: - | DE29: - | DF29: 4.5 | DG29: 4.8 | DH29: 5.1 | DI29: 5.4 | DJ29: 5.6 | DK29: 5.9
A30: MG | B30: 3144300 | C30: Nanuque | D30: =VLOOKUP(B30,Planilha1!$A:$B,2,0) -> Vale do Mucuri | E30: 31347795 | F30: EM AMERICO MACHADO | G30: Municipal | H30: - | I30: - | J30: - | K30: - | L30: - | M30: - | N30: - | O30: - | P30: - | Q30: - | R30: - | S30: - | T30: - | U30: - | V30: - | W30: - | X30: - | Y30: - | Z30: 78.7 | AA30: 78.1 | AB30: 76.2 | AC30: 86.4 | AD30: 73.7 | AE30: 0.783238 | AF30: 85.6 | AG30: 86.4 | AH30: 93.2 | AI30: 78.8 | AJ30: 85 | AK30: 0.855455 | AL30: 83.5 | AM30: 90 | AN30: 92.1 | AO30: 75 | AP30: 73.7 | AQ30: 0.818486 | AR30: 64.7 | AS30: 58.5 | AT30: 68.4 | AU30: 63.8 | AV30: 82.4 | AW30: 0.672 | AX30: 70.9 | AY30: 67.5 | AZ30: 67.2 | BA30: 74.5 | BB30: 82.1 | BC30: 0.723342 | BD30: 89.4 | BE30: 91.9 | BF30: 82 | BG30: 93.3 | BH30: 91.5 | BI30: 0.894383 | BJ30: 78.6 | BK30: 85.3 | BL30: 73.9 | BM30: 76.7 | BN30: 76.7 | BO30: 0.77926 | BP30: - | BQ30: - | BR30: - | BS30: - | BT30: - | BU30: - | BV30: - | BW30: - | BX30: - | BY30: 237.75 | BZ30: 228.71 | CA30: 4.441 | CB30: 233.48 | CC30: 235.59 | CD30: 4.4845 | CE30: 252,57 | CF30: 249,08 | CG30: 5.0275 | CH30: 231.4 | CI30: 258.48 | CJ30: 4.831333 | CK30: ND | CL30: ND | CM30: - | CN30: ND | CO30: ND | CP30: - | CQ30: ND | CR30: ND | CS30: - | CT30: - | CU30: - | CV30: - | CW30: 3.5 | CX30: 3.8 | CY30: 4.1 | CZ30: 3.2 | DA30: - | DB30: - | DC30: - | DD30: - | DE30: - | DF30: - | DG30: 3.7 | DH30: 4 | DI30: 4.2 | DJ30: 4.5 | DK30: 4.8
A31: MG | B31: 3145356 | C31: Novo Oriente de Minas | D31: =VLOOKUP(B31,Planilha1!$A:$B,2,0) -> Vale do Mucuri | E31: 31156892 | F31: EM MANOEL GONCALVES SOARES | G31: Municipal | H31: - | I31: - | J31: - | K31: - | L31: - | M31: - | N31: - | O31: - | P31: - | Q31: - | R31: - | S31: - | T31: - | U31: - | V31: - | W31: - | X31: - | Y31: - | Z31: - | AA31: - | AB31: - | AC31: - | AD31: - | AE31: - | AF31: - | AG31: - | AH31: - | AI31: - | AJ31: - | AK31: - | AL31: - | AM31: - | AN31: - | AO31: - | AP31: - | AQ31: - | AR31: 100 | AS31: 100 | AT31: 100 | AU31: 100 | AV31: 100 | AW31: 1 | AX31: - | AY31: - | AZ31: - | BA31: - | BB31: - | BC31: - | BD31: - | BE31: - | BF31: - | BG31: - | BH31: - | BI31: - | BJ31: 100 | BK31: 100 | BL31: 100 | BM31: 100 | BN31: 100 | BO31: 1 | BP31: - | BQ31: - | BR31: - | BS31: - | BT31: - | BU31: - | BV31: - | BW31: - | BX31: - | BY31: - | BZ31: - | CA31: - | CB31: - | CC31: - | CD31: - | CE31: - | CF31: - | CG31: - | CH31: 228.72 | CI31: 240.18 | CJ31: 4.481667 | CK31: - | CL31: - | CM31: - | CN31: - | CO31: - | CP31: - | CQ31: 212.63 | CR31: 207.76 | CS31: 3.673167 | CT31: - | CU31: - | CV31: - | CW31: - | CX31: - | CY31: - | CZ31: 4.5 | DA31: - | DB31: - | DC31: 3.7 | DD31: - | DE31: - | DF31: - | DG31: - | DH31: - | DI31: - | DJ31: 4.7 | DK31: 5
A32: MG | B32: 3145356 | C32: Novo Oriente de Minas | D32: =VLOOKUP(B32,Planilha1!$A:$B,2,0) -> Vale do Mucuri | E32: 31157210 | F32: EM AMERICANINHA | G32: Municipal | H32: - | I32: - | J32: - | K32: - | L32: - | M32: - | N32: - | O32: - | P32: - | Q32: - | R32: - | S32: - | T32: 80.3 | U32: 79.6 | V32: 83.9 | W32: 78.8 | X32: 77.1 | Y32: 0.79773 | Z32: - | AA32: - | AB32: - | AC32: - | AD32: - | AE32: - | AF32: - | AG32: - | AH32: - | AI32: - | AJ32: - | AK32: - | AL32: - | AM32: - | AN32: - | AO32: - | AP32: - | AQ32: - | AR32: - | AS32: - | AT32: - | AU32: - | AV32: - | AW32: - | AX32: - | AY32: - | AZ32: - | BA32: - | BB32: - | BC32: - | BD32: - | BE32: - | BF32: - | BG32: - | BH32: - | BI32: - | BJ32: - | BK32: - | BL32: - | BM32: - | BN32: - | BO32: - | BP32: - | BQ32: - | BR32: - | BS32: - | BT32: - | BU32: - | BV32: 227.12 | BW32: 222.07 | BX32: 4.153167 | BY32: - | BZ32: - | CA32: - | CB32: - | CC32: - | CD32: - | CE32: - | CF32: - | CG32: - | CH32: - | CI32: - | CJ32: - | CK32: - | CL32: - | CM32: - | CN32: - | CO32: - | CP32: - | CQ32: - | CR32: - | CS32: - | CT32: - | CU32: - | CV32: 3.3 | CW32: - | CX32: - | CY32: - | CZ32: - | DA32: - | DB32: - | DC32: - | DD32: - | DE32: - | DF32: 3.5 | DG32: 3.7 | DH32: 4.1 | DI32: 4.3 | DJ32: 4.6 | DK32: 4.9
A33: MG | B33: 3145356 | C33: Novo Oriente de Minas | D33: =VLOOKUP(B33,Planilha1!$A:$B,2,0) -> Vale do Mucuri | E33: 31157279 | F33: EM DOMICIO PINTO MIRANDA | G33: Municipal | H33: - | I33: - | J33: - | K33: - | L33: - | M33: - | N33: - | O33: - | P33: - | Q33: - | R33: - | S33: - | T33: - | U33: - | V33: - | W33: - | X33: - | Y33: - | Z33: - | AA33: - | AB33: - | AC33: - | AD33: - | AE33: - | AF33: - | AG33: - | AH33: - | AI33: - | AJ33: - | AK33: - | AL33: - | AM33: - | AN33: - | AO33: - | AP33: - | AQ33: - | AR33: 96.2 | AS33: 100 | AT33: 100 | AU33: 100 | AV33: 87.5 | AW33: 0.965517 | AX33: - | AY33: - | AZ33: - | BA33: - | BB33: - | BC33: - | BD33: - | BE33: - | BF33: - | BG33: - | BH33: - | BI33: - | BJ33: - | BK33: - | BL33: - | BM33: - | BN33: - | BO33: - | BP33: - | BQ33: - | BR33: - | BS33: - | BT33: - | BU33: - | BV33: - | BW33: - | BX33: - | BY33: - | BZ33: - | CA33: - | CB33: - | CC33: - | CD33: - | CE33: - | CF33: - | CG33: - | CH33: 220.63 | CI33: 214.47 | CJ33: 3.918333 | CK33: - | CL33: - | CM33: - | CN33: - | CO33: - | CP33: - | CQ33: - | CR33: - | CS33: - | CT33: - | CU33: - | CV33: - | CW33: - | CX33: - | CY33: - | CZ33: 3.8 | DA33: - | DB33: - | DC33: - | DD33: - | DE33: - | DF33: - | DG33: - | DH33: - | DI33: - | DJ33: 4 | DK33: 4.3
A34: MG | B34: 3152402 | C34: Poté | D34: =VLOOKUP(B34,Planilha1!$A:$B,2,0) -> Vale do Mucuri | E34: 31156299 | F34: EM FREI GASPAR | G34: Municipal | H34: - | I34: - | J34: - | K34: - | L34: - | M34: - | N34: - | O34: - | P34: - | Q34: - | R34: - | S34: - | T34: - | U34: - | V34: - | W34: - | X34: - | Y34: - | Z34: - | AA34: - | AB34: - | AC34: - | AD34: - | AE34: - | AF34: - | AG34: - | AH34: - | AI34: - | AJ34: - | AK34: - | AL34: - | AM34: - | AN34: - | AO34: - | AP34: - | AQ34: - | AR34: 100 | AS34: 100 | AT34: 100 | AU34: 100 | AV34: 100 | AW34: 1 | AX34: - | AY34: - | AZ34: - | BA34: - | BB34: - | BC34: - | BD34: - | BE34: - | BF34: - | BG34: - | BH34: - | BI34: - | BJ34: - | BK34: - | BL34: - | BM34: - | BN34: - | BO34: - | BP34: - | BQ34: - | BR34: - | BS34: - | BT34: - | BU34: - | BV34: - | BW34: - | BX34: - | BY34: - | BZ34: - | CA34: - | CB34: - | CC34: - | CD34: - | CE34: - | CF34: - | CG34: - | CH34: 242.17 | CI34: 235.15 | CJ34: 4.622 | CK34: - | CL34: - | CM34: - | CN34: - | CO34: - | CP34: - | CQ34: - | CR34: - | CS34: - | CT34: - | CU34: - | CV34: - | CW34: - | CX34: - | CY34: - | CZ34: 4.6 | DA34: - | DB34: - | DC34: - | DD34: - | DE34: - | DF34: - | DG34: - | DH34: - | DI34: - | DJ34: 4.9 | DK34: 5.1
A35: MG | B35: 3152402 | C35: Poté | D35: =VLOOKUP(B35,Planilha1!$A:$B,2,0) -> Vale do Mucuri | E35: 31347396 | F35: EM PREF OMAR AFFONSO DA SILVA | G35: Municipal | H35: - | I35: - | J35: - | K35: - | L35: - | M35: - | N35: - | O35: - | P35: - | Q35: - | R35: - | S35: - | T35: - | U35: - | V35: - | W35: - | X35: - | Y35: - | Z35: - | AA35: - | AB35: - | AC35: - | AD35: - | AE35: - | AF35: 94.7 | AG35: 91.6 | AH35: 98.5 | AI35: 97.4 | AJ35: 93.9 | AK35: 0.952701 | AL35: 93.8 | AM35: 88.3 | AN35: 93.3 | AO35: 97.5 | AP35: 98.1 | AQ35: 0.941326 | AR35: 94.6 | AS35: 87.8 | AT35: 97.5 | AU35: 95.8 | AV35: 98 | AW35: 0.945885 | AX35: 87.7 | AY35: 89.7 | AZ35: 79.1 | BA35: 89.5 | BB35: 92.4 | BC35: 0.873626 | BD35: 98.4 | BE35: 98.7 | BF35: 98.4 | BG35: 97 | BH35: 100 | BI35: 0.985135 | BJ35: 95.4 | BK35: 93.9 | BL35: 95.8 | BM35: 94.9 | BN35: 97.7 | BO35: 0.955546 | BP35: - | BQ35: - | BR35: - | BS35: - | BT35: - | BU35: - | BV35: - | BW35: - | BX35: - | BY35: - | BZ35: - | CA35: - | CB35: 249.07 | CC35: 249.86 | CD35: 4.982167 | CE35: 243,79 | CF35: 249,12 | CG35: 4.881833 | CH35: 256.56 | CI35: 268.52 | CJ35: 5.418 | CK35: 264.09 | CL35: 270.66 | CM35: 5.579167 | CN35: ND | CO35: ND | CP35: - | CQ35: 235.63 | CR35: 247.65 | CS35: 4.721333 | CT35: - | CU35: - | CV35: - | CW35: - | CX35: 4.7 | CY35: 4.6 | CZ35: 5.1 | DA35: 4.9 | DB35: - | DC35: 4.5 | DD35: - | DE35: - | DF35: - | DG35: - | DH35: 5 | DI35: 5.2 | DJ35: 5.5 | DK35: 5.7
A36: MG | B36: 3157658 | C36: Santa Helena de Minas | D36: =VLOOKUP(B36,Planilha1!$A:$B,2,0) -> Vale do Mucuri | E36: 31150037 | F36: ESCOLA MUNICIPAL BARAO DO RIO BRANCO | G36: Municipal | H36: - | I36: - | J36: - | K36: - | L36: - | M36: - | N36: - | O36: - | P36: - | Q36: - | R36: - | S36: - | T36: - | U36: - | V36: - | W36: - | X36: - | Y36: - | Z36: - | AA36: - | AB36: - | AC36: - | AD36: - | AE36: - | AF36: - | AG36: - | AH36: - | AI36: - | AJ36: - | AK36: - | AL36: 88.4 | AM36: 94.7 | AN36: 81.3 | AO36: 93.8 | AP36: 83.3 | AQ36: 0.878627 | AR36: 92.2 | AS36: 100 | AT36: 78.9 | AU36: 94.7 | AV36: 100 | AW36: 0.925199 | AX36: 97.8 | AY36: 85.7 | AZ36: 100 | BA36: 100 | BB36: 100 | BC36: 0.959955 | BD36: 89.4 | BE36: 100 | BF36: 87.5 | BG36: 90.9 | BH36: 84.6 | BI36: 0.903955 | BJ36: 95.7 | BK36: 100 | BL36: 100 | BM36: 87.5 | BN36: 92.9 | BO36: 0.948028 | BP36: - | BQ36: - | BR36: - | BS36: - | BT36: - | BU36: - | BV36: - | BW36: - | BX36: - | BY36: - | BZ36: - | CA36: - | CB36: - | CC36: - | CD36: - | CE36: 234,52 | CF36: 229,89 | CG36: 4.406833 | CH36: 244.47 | CI36: 238.8 | CJ36: 4.721167 | CK36: 252.24 | CL36: 262.78 | CM36: 5.250333 | CN36: 219.42 | CO36: 224.38 | CP36: 4.063333 | CQ36: 268.79 | CR36: 278.17 | CS36: 5.782667 | CT36: - | CU36: - | CV36: - | CW36: - | CX36: - | CY36: 3.9 | CZ36: 4.4 | DA36: 5 | DB36: 3.7 | DC36: 5.5 | DD36: - | DE36: - | DF36: - | DG36: - | DH36: - | DI36: 4.1 | DJ36: 4.4 | DK36: 4.6
A37: MG | B37: 3166709 | C37: Serra dos Aimorés | D37: =VLOOKUP(B37,Planilha1!$A:$B,2,0) -> Vale do Mucuri | E37: 31211362 | F37: EM DE ENS FUND 1 A 8 S | G37: Municipal | H37: - | I37: - | J37: - | K37: - | L37: - | M37: - | N37: 84.3 | O37: - | P37: - | Q37: - | R37: 84.3 | S37: 0.843 | T37: - | U37: - | V37: - | W37: - | X37: - | Y37: - | Z37: - | AA37: - | AB37: - | AC37: - | AD37: - | AE37: - | AF37: - | AG37: - | AH37: - | AI37: - | AJ37: - | AK37: - | AL37: - | AM37: - | AN37: - | AO37: - | AP37: - | AQ37: - | AR37: - | AS37: - | AT37: - | AU37: - | AV37: - | AW37: - | AX37: - | AY37: - | AZ37: - | BA37: - | BB37: - | BC37: - | BD37: - | BE37: - | BF37: - | BG37: - | BH37: - | BI37: - | BJ37: - | BK37: - | BL37: - | BM37: - | BN37: - | BO37: - | BP37: - | BQ37: - | BR37: - | BS37: 212.82 | BT37: 196.83 | BU37: 3.494167 | BV37: - | BW37: - | BX37: - | BY37: - | BZ37: - | CA37: - | CB37: - | CC37: - | CD37: - | CE37: - | CF37: - | CG37: - | CH37: - | CI37: - | CJ37: - | CK37: - | CL37: - | CM37: - | CN37: - | CO37: - | CP37: - | CQ37: - | CR37: - | CS37: - | CT37: - | CU37: 2.9 | CV37: - | CW37: - | CX37: - | CY37: - | CZ37: - | DA37: - | DB37: - | DC37: - | DD37: - | DE37: 3 | DF37: 3.2 | DG37: 3.6 | DH37: 3.9 | DI37: 4.2 | DJ37: 4.4 | DK37: 4.7
A38: MG | B38: 3168606 | C38: Teófilo Otoni | D38: =VLOOKUP(B38,Planilha1!$A:$B,2,0) -> Vale do Mucuri | E38: 31156868 | F38: ESCOLA MUNICIPAL AGRICOLA GERALDO LEAO LOPES | G38: Municipal | H38: - | I38: - | J38: - | K38: - | L38: - | M38: - | N38: - | O38: - | P38: - | Q38: - | R38: - | S38: - | T38: 67.2 | U38: 56.4 | V38: 66.7 | W38: 76.9 | X38: 76.2 | Y38: 0.679691 | Z38: 80.7 | AA38: 71.4 | AB38: 75 | AC38: - | AD38: 93.3 | AE38: 0.78829 | AF38: 78.9 | AG38: 77.8 | AH38: 75.6 | AI38: 72.7 | AJ38: 95 | AK38: 0.794242 | AL38: - | AM38: - | AN38: - | AO38: - | AP38: - | AQ38: - | AR38: 70.3 | AS38: 60.7 | AT38: 65.5 | AU38: 67.9 | AV38: 88.5 | AW38: 0.692417 | AX38: 85.6 | AY38: 78.6 | AZ38: 75 | BA38: 95 | BB38: 100 | BC38: 0.858695 | BD38: - | BE38: - | BF38: - | BG38: - | BH38: - | BI38: - | BJ38: 82.1 | BK38: 87.5 | BL38: 80 | BM38: 76 | BN38: 88.9 | BO38: 0.827557 | BP38: - | BQ38: - | BR38: - | BS38: - | BT38: - | BU38: - | BV38: 223 | BW38: 222.9 | BX38: 4.098333 | BY38: ND | BZ38: ND | CA38: - | CB38: 245.54 | CC38: 238.92 | CD38: 4.741 | CE38: - | CF38: - | CG38: - | CH38: 240.85 | CI38: 248.13 | CJ38: 4.816333 | CK38: 234.48 | CL38: 233.71 | CM38: 4.469833 | CN38: - | CO38: - | CP38: - | CQ38: 226.37 | CR38: 214.23 | CS38: 4.01 | CT38: - | CU38: - | CV38: 2.8 | CW38: - | CX38: 3.8 | CY38: - | CZ38: 3.3 | DA38: 3.8 | DB38: - | DC38: 3.3 | DD38: - | DE38: - | DF38: 2.9 | DG38: 3.2 | DH38: 3.5 | DI38: 3.8 | DJ38: 4.1 | DK38: 4.3
A39: MG | B39: 3168606 | C39: Teófilo Otoni | D39: =VLOOKUP(B39,Planilha1!$A:$B,2,0) -> Vale do Mucuri | E39: 31157155 | F39: EM SIDONIO OTTONI | G39: Municipal | H39: 41.7 | I39: 28.9 | J39: 41.9 | K39: 48 | L39: 54.9 | M39: 0.410186 | N39: 46.3 | O39: 39.2 | P39: 42.9 | Q39: 62.8 | R39: 48.9 | S39: 0.469518 | T39: 51.5 | U39: 38.4 | V39: 47.8 | W39: 60.7 | X39: 70 | Y39: 0.514652 | Z39: 67.3 | AA39: 63.6 | AB39: 60.4 | AC39: 72.6 | AD39: 75.7 | AE39: 0.674949 | AF39: 66.1 | AG39: 74.6 | AH39: 58 | AI39: 61.1 | AJ39: 72.6 | AK39: 0.658036 | AL39: 60.3 | AM39: 61.3 | AN39: 41.9 | AO39: 60.9 | AP39: 68.1 | AQ39: 0.561134 | AR39: 55.3 | AS39: 46.2 | AT39: 43.2 | AU39: 71 | AV39: 78.1 | AW39: 0.558022 | AX39: 77.9 | AY39: 73.5 | AZ39: 81.8 | BA39: 76.3 | BB39: 92 | BC39: 0.803114 | BD39: 79.2 | BE39: 66.7 | BF39: 84.8 | BG39: 81 | BH39: 88.2 | BI39: 0.792574 | BJ39: 75 | BK39: 64.7 | BL39: 68.8 | BM39: 90.7 | BN39: 89.6 | BO39: 0.766623 | BP39: 240.97 | BQ39: 233.72 | BR39: 4.578096 | BS39: 236.37 | BT39: 229.93 | BU39: 4.438333 | BV39: 226.57 | BW39: 216.66 | BX39: 4.053833 | BY39: 259.73 | BZ39: 256.33 | CA39: 5.267667 | CB39: 247.29 | CC39: 238.48 | CD39: 4.762833 | CE39: 245,51 | CF39: 246,77 | CG39: 4.871333 | CH39: ND | CI39: ND | CJ39: - | CK39: 262.64 | CL39: 266.69 | CM39: 5.488833 | CN39: ND | CO39: ND | CP39: - | CQ39: 245.88 | CR39: 239.94 | CS39: 4.763667 | CT39: 1.9 | CU39: 2.1 | CV39: 2.1 | CW39: 3.6 | CX39: 3.1 | CY39: 2.7 | CZ39: - | DA39: 4.4 | DB39: - | DC39: 3.7 | DD39: 2 | DE39: 2.5 | DF39: 3 | DG39: 3.7 | DH39: 4.2 | DI39: 4.5 | DJ39: 4.7 | DK39: 5
A40: MG | B40: 3168606 | C40: Teófilo Otoni | D40: =VLOOKUP(B40,Planilha1!$A:$B,2,0) -> Vale do Mucuri | E40: 31157163 | F40: EM AGRICOLA INACIO PEREIRA GUIMARAES | G40: Municipal | H40: - | I40: - | J40: - | K40: - | L40: - | M40: - | N40: - | O40: - | P40: - | Q40: - | R40: - | S40: - | T40: - | U40: - | V40: - | W40: - | X40: - | Y40: - | Z40: 75.3 | AA40: 73.9 | AB40: 72.7 | AC40: 64.4 | AD40: 92.3 | AE40: 0.745585 | AF40: 55.9 | AG40: 54.1 | AH40: 58.1 | AI40: 56.5 | AJ40: 56.4 | AK40: 0.562385 | AL40: - | AM40: - | AN40: - | AO40: - | AP40: - | AQ40: - | AR40: 69 | AS40: 65.8 | AT40: 72.4 | AU40: 85 | AV40: 51.4 | AW40: 0.664124 | AX40: 70.8 | AY40: 63.4 | AZ40: 79.3 | BA40: 90 | BB40: 56.5 | BC40: 0.699381 | BD40: - | BE40: - | BF40: - | BG40: - | BH40: - | BI40: - | BJ40: 71.3 | BK40: 82.4 | BL40: 87 | BM40: 56.5 | BN40: 62.5 | BO40: 0.697724 | BP40: - | BQ40: - | BR40: - | BS40: - | BT40: - | BU40: - | BV40: - | BW40: - | BX40: - | BY40: 233.35 | BZ40: 223.04 | CA40: 4.273167 | CB40: 230.95 | CC40: 225.46 | CD40: 4.2735 | CE40: - | CF40: - | CG40: - | CH40: ND | CI40: ND | CJ40: - | CK40: ND | CL40: ND | CM40: - | CN40: - | CO40: - | CP40: - | CQ40: 222.85 | CR40: 223.92 | CS40: 4.112833 | CT40: - | CU40: - | CV40: - | CW40: 3.2 | CX40: 2.4 | CY40: - | CZ40: - | DA40: - | DB40: - | DC40: 2.9 | DD40: - | DE40: - | DF40: - | DG40: 3.4 | DH40: 3.7 | DI40: 3.9 | DJ40: 4.2 | DK40: 4.5
A41: MG | B41: 3168606 | C41: Teófilo Otoni | D41: =VLOOKUP(B41,Planilha1!$A:$B,2,0) -> Vale do Mucuri | E41: 31228591 | F41: EM IRMA MARIA AMALIA | G41: Municipal | H41: 83.1 | I41: 87.2 | J41: 78.4 | K41: 83.4 | L41: 83.5 | M41: 0.830057 | N41: 82 | O41: 89.3 | P41: 82.6 | Q41: 77.1 | R41: 75.6 | S41: 0.808041 | T41: 85.2 | U41: 86 | V41: 82.4 | W41: 83.2 | X41: 89.5 | Y41: 0.851857 | Z41: 84 | AA41: 79.5 | AB41: 85.5 | AC41: 83.2 | AD41: 88.6 | AE41: 0.840682 | AF41: 86 | AG41: 85 | AH41: 83.9 | AI41: 85.4 | AJ41: 90.5 | AK41: 0.861271 | AL41: 80.8 | AM41: 80.5 | AN41: 77.6 | AO41: 91 | AP41: 73.4 | AQ41: 0.801251 | AR41: 81.9 | AS41: 82.8 | AT41: 78.7 | AU41: 80.5 | AV41: 86 | AW41: 0.819101 | AX41: 83.1 | AY41: 85.1 | AZ41: 76.2 | BA41: 86.3 | BB41: 86.5 | BC41: 0.832944 | BD41: 92 | BE41: 90.2 | BF41: 88.9 | BG41: 93.2 | BH41: 97.5 | BI41: 0.923338 | BJ41: 91.2 | BK41: 92.6 | BL41: 87 | BM41: 90.7 | BN41: 95.6 | BO41: 0.91368 | BP41: 293.24 | BQ41: 266.17 | BR41: 5.990275 | BS41: 301.28 | BT41: 276.93 | BU41: 6.3035 | BV41: 318.07 | BW41: 290.74 | BX41: 6.8135 | BY41: 311.95 | BZ41: 289.86 | CA41: 6.696833 | CB41: 297.71 | CC41: 285.42 | CD41: 6.3855 | CE41: 298,65 | CF41: 288,90 | CG41: 6.459167 | CH41: 302.38 | CI41: 295.2 | CJ41: 6.626333 | CK41: 301.74 | CL41: 292.12 | CM41: 6.564333 | CN41: 283.64 | CO41: 284.81 | CP41: 6.140833 | CQ41: 294.24 | CR41: 285.85 | CS41: 6.334833 | CT41: 5 | CU41: 5.1 | CV41: 5.8 | CW41: 5.6 | CX41: 5.5 | CY41: 5.2 | CZ41: 5.4 | DA41: 5.5 | DB41: 5.7 | DC41: 5.8 | DD41: 5 | DE41: 5.1 | DF41: 5.4 | DG41: 5.8 | DH41: 6.1 | DI41: 6.3 | DJ41: 6.5 | DK41: 6.7
A42: MG | B42: 3168606 | C42: Teófilo Otoni | D42: =VLOOKUP(B42,Planilha1!$A:$B,2,0) -> Vale do Mucuri | E42: 31305669 | F42: EM NOSSA SENHORA APARECIDA | G42: Municipal | H42: 63.3 | I42: 63.6 | J42: 75.4 | K42: 43.3 | L42: 73 | M42: 0.608095 | N42: 78.7 | O42: 81.6 | P42: 77.5 | Q42: 71.8 | R42: 80.9 | S42: 0.777505 | T42: 71.8 | U42: 68.4 | V42: 70.9 | W42: 63.8 | X42: 84.5 | Y42: 0.711332 | Z42: 65.9 | AA42: 56.8 | AB42: 68.5 | AC42: 69.8 | AD42: 73.7 | AE42: 0.665565 | AF42: 67.8 | AG42: 59 | AH42: 71.1 | AI42: 65.7 | AJ42: 90.6 | AK42: 0.698421 | AL42: 69.7 | AM42: 57.4 | AN42: 73.7 | AO42: 73.1 | AP42: 82.8 | AQ42: 0.704879 | AR42: 90.5 | AS42: 86.6 | AT42: 87.8 | AU42: 90.2 | AV42: 100 | AW42: 0.908609 | AX42: 79.4 | AY42: 83.1 | AZ42: 81.6 | BA42: 74.1 | BB42: 73.3 | BC42: 0.77781 | BD42: 87.9 | BE42: 83.3 | BF42: 87.3 | BG42: 88.4 | BH42: 91.9 | BI42: 0.876171 | BJ42: 71.8 | BK42: 67.3 | BL42: 62 | BM42: 75 | BN42: 88.2 | BO42: 0.718661 | BP42: 229.57 | BQ42: 215.27 | BR42: 4.080722 | BS42: 217.32 | BT42: 222.02 | BU42: 3.989 | BV42: 221.97 | BW42: 232.34 | BX42: 4.2385 | BY42: 253.04 | BZ42: 230.12 | CA42: 4.719333 | CB42: 258.38 | CC42: 248.98 | CD42: 5.122667 | CE42: 246,56 | CF42: 245,96 | CG42: 4.875333 | CH42: 240.94 | CI42: 256.46 | CJ42: 4.956667 | CK42: 239.72 | CL42: 249.84 | CM42: 4.826 | CN42: ND | CO42: ND | CP42: - | CQ42: ND | CR42: ND | CS42: - | CT42: 2.5 | CU42: 3.1 | CV42: 3 | CW42: 3.1 | CX42: 3.6 | CY42: 3.4 | CZ42: 4.5 | DA42: 3.8 | DB42: - | DC42: - | DD42: 2.5 | DE42: 2.7 | DF42: 3 | DG42: 3.5 | DH42: 3.9 | DI42: 4.1 | DJ42: 4.4 | DK42: 4.7
...

Sheet Planilha1
A1: Código Município Completo
A2: 3100906 | B2: Vale do Mucuri
A3: 3104700 | B3: Vale do Mucuri
A4: 3106606 | B4: Vale do Mucuri
A5: 3113701 | B5: Vale do Mucuri
A6: 3115458 | B6: Vale do Mucuri
A7: 3120151 | B7: Vale do Mucuri
A8: 3126752 | B8: Vale do Mucuri
A9: 3126802 | B9: Vale do Mucuri
A10: 3127057 | B10: Vale do Mucuri
A11: 3132305 | B11: Vale do Mucuri
A12: 3137007 | B12: Vale do Mucuri
A13: 3138906 | B13: Vale do Mucuri
... A24: 3170305 | B24: Vale do Mucuri
