Workbook

Sheet IDEB_AI_MUNICÍPIOS
B1: Ministério da Educação
B2: Instituto Nacional de Estudos e Pesquisas Educacionais Anísio Teixeira
A4: Ensino Fundamental Regular - Anos Iniciais
A5: Indicadores educacionais compostos por: Taxa de Aprovação, SAEB e IDEB nos anos de 2005, 2007, 2009, 2011, 2013, 2015, 2017, 2019, 20212 e 2023 e Metas do 1º ciclo do Ideb3,4 (2007-2021). Os dados estão dimensionados por município e organizados por rede de ensino.
A7: Sigla da UF | B7: Código do Município | C7: Nome do Município | D7: Mesorregião | E7: Rede | F7: Taxa de Aprovação - 2005 | M7: Taxa de Aprovação - 2007 | T7: Taxa de Aprovação - 2009 | AA7: Taxa de Aprovação - 2011 | AH7: Taxa de Aprovação - 2013 | AO7: Taxa de Aprovação - 2015 | AV7: Taxa de Aprovação - 2017 | BC7: Taxa de Aprovação - 2019 | BJ7: Taxa de Aprovação - 20212 | BQ7: Taxa de Aprovação - 2023 | BX7: Nota SAEB - 2005 | CA7: Nota SAEB - 2007 | CD7: Nota SAEB - 2009 | CG7: Nota SAEB - 2011 | CJ7: Nota SAEB - 2013 | CM7: Nota SAEB - 2015 | CP7: Nota SAEB - 2017 | CS7: Nota SAEB - 2019 | CV7: Nota SAEB - 20212 | CY7: Nota SAEB - 2023 | DB7: IDEB 2005 (N x P) | DC7: IDEB 2007 (N x P) | DD7: IDEB 2009 (N x P) | DE7: IDEB 2011 (N x P) | DF7: IDEB 2013 (N x P) | DG7: IDEB 2015 (N x P) | DH7: IDEB 2017 (N x P) | DI7: IDEB 2019 (N x P) | DJ7: IDEB 20212 (N x P) | DK7: IDEB 2023 (N x P) | DL7: Metas do 1º ciclo do Ideb3,4 (2007-2021)
BX8: Matemática | BY8: Língua Portuguesa | BZ8: Nota Média Padronizada (N) | CA8: Matemática | CB8: Língua Portuguesa | CC8: Nota Média Padronizada (N) | CD8: Matemática | CE8: Língua Portuguesa | CF8: Nota Média Padronizada (N) | CG8: Matemática | CH8: Língua Portuguesa | CI8: Nota Média Padronizada (N) | CJ8: Matemática | CK8: Língua Portuguesa | CL8: Nota Média Padronizada (N) | CM8: Matemática | CN8: Língua Portuguesa | CO8: Nota Média Padronizada (N) | CP8: Matemática | CQ8: Língua Portuguesa | CR8: Nota Média Padronizada (N) | CS8: Matemática | CT8: Língua Portuguesa | CU8: Nota Média Padronizada (N) | CV8: Matemática | CW8: Língua Portuguesa | CX8: Nota Média Padronizada (N) | CY8: Matemática | CZ8: Língua Portuguesa | DA8: Nota Média Padronizada (N)
F9: 1º ao 5º ano | G9: 1º | H9: 2º | I9: 3º | J9: 4º | K9: 5º | L9: Indicador de Rendimento (P) | M9: 1º ao 5º ano | N9: 1º | O9: 2º | P9: 3º | Q9: 4º | R9: 5º | S9: Indicador de Rendimento (P) | T9: 1º ao 5º ano | U9: 1º | V9: 2º | W9: 3º | X9: 4º | Y9: 5º | Z9: Indicador de Rendimento (P) | AA9: 1º ao 5º ano | AB9: 1º | AC9: 2º | AD9: 3º | AE9: 4º | AF9: 5º | AG9: Indicador de Rendimento (P) | AH9: 1º ao 5º ano | AI9: 1º | AJ9: 2º | AK9: 3º | AL9: 4º | AM9: 5º | AN9: Indicador de Rendimento (P) | AO9: 1º ao 5º ano | AP9: 1º | AQ9: 2º | AR9: 3º | AS9: 4º | AT9: 5º | AU9: Indicador de Rendimento (P) | AV9: 1º ao 5º ano | AW9: 1º | AX9: 2º | AY9: 3º | AZ9: 4º | BA9: 5º | BB9: Indicador de Rendimento (P) | BC9: 1º ao 5º ano | BD9: 1º | BE9: 2º | BF9: 3º | BG9: 4º | BH9: 5º | BI9: Indicador de Rendimento (P) | BJ9: 1º ao 5º ano | BK9: 1º | BL9: 2º | BM9: 3º | BN9: 4º | BO9: 5º | BP9: Indicador de Rendimento (P) | BQ9: 1º ao 5º ano | BR9: 1º | BS9: 2º | BT9: 3º | BU9: 4º | BV9: 5º | BW9: Indicador de Rendimento (P) | DL9: 2007 | DM9: 2009 | DN9: 2011 | DO9: 2013 | DP9: 2015 | DQ9: 2017 | DR9: 2019 | DS9: 2021
A10: SG_UF | B10: CO_MUNICIPIO | C10: NO_MUNICIPIO | E10: REDE | F10: VL_APROVACAO_2005_SI_4 | G10: VL_APROVACAO_2005_SI | H10: VL_APROVACAO_2005_1 | I10: VL_APROVACAO_2005_2 | J10: VL_APROVACAO_2005_3 | K10: VL_APROVACAO_2005_4 | L10: VL_INDICADOR_REND_2005 | M10: VL_APROVACAO_2007_SI_4 | N10: VL_APROVACAO_2007_SI | O10: VL_APROVACAO_2007_1 | P10: VL_APROVACAO_2007_2 | Q10: VL_APROVACAO_2007_3 | R10: VL_APROVACAO_2007_4 | S10: VL_INDICADOR_REND_2007 | T10: VL_APROVACAO_2009_SI_4 | U10: VL_APROVACAO_2009_SI | V10: VL_APROVACAO_2009_1 | W10: VL_APROVACAO_2009_2 | X10: VL_APROVACAO_2009_3 | Y10: VL_APROVACAO_2009_4 | Z10: VL_INDICADOR_REND_2009 | AA10: VL_APROVACAO_2011_SI_4 | AB10: VL_APROVACAO_2011_SI | AC10: VL_APROVACAO_2011_1 | AD10: VL_APROVACAO_2011_2 | AE10: VL_APROVACAO_2011_3 | AF10: VL_APROVACAO_2011_4 | AG10: VL_INDICADOR_REND_2011 | AH10: VL_APROVACAO_2013_SI_4 | AI10: VL_APROVACAO_2013_SI | AJ10: VL_APROVACAO_2013_1 | AK10: VL_APROVACAO_2013_2 | AL10: VL_APROVACAO_2013_3 | AM10: VL_APROVACAO_2013_4 | AN10: VL_INDICADOR_REND_2013 | AO10: VL_APROVACAO_2015_SI_4 | AP10: VL_APROVACAO_2015_SI | AQ10: VL_APROVACAO_2015_1 | AR10: VL_APROVACAO_2015_2 | AS10: VL_APROVACAO_2015_3 | AT10: VL_APROVACAO_2015_4 | AU10: VL_INDICADOR_REND_2015 | AV10: VL_APROVACAO_2017_SI_4 | AW10: VL_APROVACAO_2017_SI | AX10: VL_APROVACAO_2017_1 | AY10: VL_APROVACAO_2017_2 | AZ10: VL_APROVACAO_2017_3 | BA10: VL_APROVACAO_2017_4 | BB10: VL_INDICADOR_REND_2017 | BC10: VL_APROVACAO_2019_SI_4 | BD10: VL_APROVACAO_2019_SI | BE10: VL_APROVACAO_2019_1 | BF10: VL_APROVACAO_2019_2 | BG10: VL_APROVACAO_2019_3 | BH10: VL_APROVACAO_2019_4 | BI10: VL_INDICADOR_REND_2019 | BJ10: VL_APROVACAO_2021_SI_4 | BK10: VL_APROVACAO_2021_SI | BL10: VL_APROVACAO_2021_1 | BM10: VL_APROVACAO_2021_2 | BN10: VL_APROVACAO_2021_3 | BO10: VL_APROVACAO_2021_4 | BP10: VL_INDICADOR_REND_2021 | BQ10: VL_APROVACAO_2023_SI_4 | BR10: VL_APROVACAO_2023_SI | BS10: VL_APROVACAO_2023_1 | BT10: VL_APROVACAO_2023_2 | BU10: VL_APROVACAO_2023_3 | BV10: VL_APROVACAO_2023_4 | BW10: VL_INDICADOR_REND_2023 | BX10: VL_NOTA_MATEMATICA_2005 | BY10: VL_NOTA_PORTUGUES_2005 | BZ10: VL_NOTA_MEDIA_2005 | CA10: VL_NOTA_MATEMATICA_2007 | CB10: VL_NOTA_PORTUGUES_2007 | CC10: VL_NOTA_MEDIA_2007 | CD10: VL_NOTA_MATEMATICA_2009 | CE10: VL_NOTA_PORTUGUES_2009 | CF10: VL_NOTA_MEDIA_2009 | CG10: VL_NOTA_MATEMATICA_2011 | CH10: VL_NOTA_PORTUGUES_2011 | CI10: VL_NOTA_MEDIA_2011 | CJ10: VL_NOTA_MATEMATICA_2013 | CK10: VL_NOTA_PORTUGUES_2013 | CL10: VL_NOTA_MEDIA_2013 | CM10: VL_NOTA_MATEMATICA_2015 | CN10: VL_NOTA_PORTUGUES_2015 | CO10: VL_NOTA_MEDIA_2015 | CP10: VL_NOTA_MATEMATICA_2017 | CQ10: VL_NOTA_PORTUGUES_2017 | CR10: VL_NOTA_MEDIA_2017 | CS10: VL_NOTA_MATEMATICA_2019 | CT10: VL_NOTA_PORTUGUES_2019 | CU10: VL_NOTA_MEDIA_2019 | CV10: VL_NOTA_MATEMATICA_2021 | CW10: VL_NOTA_PORTUGUES_2021 | CX10: VL_NOTA_MEDIA_2021 | CY10: VL_NOTA_MATEMATICA_2023 | CZ10: VL_NOTA_PORTUGUES_2023 | DA10: VL_NOTA_MEDIA_2023 | DB10: VL_OBSERVADO_2005 | DC10: VL_OBSERVADO_2007 | DD10: VL_OBSERVADO_2009 | DE10: VL_OBSERVADO_2011 | DF10: VL_OBSERVADO_2013 | DG10: VL_OBSERVADO_2015 | DH10: VL_OBSERVADO_2017 | DI10: VL_OBSERVADO_2019 | DJ10: VL_OBSERVADO_2021 | DK10: VL_OBSERVADO_2023 | DL10: VL_PROJECAO_2007 | DM10: VL_PROJECAO_2009 | DN10: VL_PROJECAO_2011 | DO10: VL_PROJECAO_2013 | DP10: VL_PROJECAO_2015 | DQ10: VL_PROJECAO_2017 | DR10: VL_PROJECAO_2019 | DS10: VL_PROJECAO_2021
A11: MG | B11: 3100906 | C11: Águas Formosas | D11: =VLOOKUP(B11,Planilha1!$A:$B,2,0) -> Vale do Mucuri | E11: Municipal | F11: - | G11: - | H11: - | I11: - | J11: - | K11: - | L11: - | M11: 76.4 | N11: 83.5 | O11: 81.8 | P11: 60.6 | Q11: 83.2 | R11: 71.6 | S11: 0.749756 | T11: 78.3 | U11: 100 | V11: 79.4 | W11: 68.9 | X11: 98 | Y11: 60.2 | Z11: 0.782183 | AA11: 99.7 | AB11: 98 | AC11: 100 | AD11: 100 | AE11: 100 | AF11: 100 | AG11: 0.995935 | AH11: - | AI11: - | AJ11: - | AK11: - | AL11: - | AM11: - | AN11: - | AO11: - | AP11: - | AQ11: - | AR11: - | AS11: - | AT11: - | AU11: - | AV11: - | AW11: - | AX11: - | AY11: - | AZ11: - | BA11: - | BB11: - | BC11: - | BD11: - | BE11: - | BF11: - | BG11: - | BH11: - | BI11: - | BJ11: - | BK11: - | BL11: - | BM11: - | BN11: - | BO11: - | BP11: - | BQ11: - | BR11: - | BS11: - | BT11: - | BU11: - | BV11: - | BW11: - | BX11: - | BY11: - | BZ11: - | CA11: 155.27 | CB11: 147.49 | CC11: 3.608857 | CD11: ND | CE11: ND | CF11: - | CG11: 185.04 | CH11: 171.65 | CI11: 4.61626 | CJ11: - | CK11: - | CL11: - | CM11: - | CN11: - | CO11: - | CP11: - | CQ11: - | CR11: - | CS11: - | CT11: - | CU11: - | CV11: - | CW11: - | CX11: - | CY11: - | CZ11: - | DA11: - | DB11: - | DC11: 2.7 | DD11: - | DE11: 4.6 | DF11: - | DG11: - | DH11: - | DI11: - | DJ11: - | DK11: - | DL11: - | DM11: 2.9 | DN11: 3.2 | DO11: 3.5 | DP11: 3.8 | DQ11: 4.1 | DR11: 4.4 | DS11: 4.7
A12: MG | B12: 3104700 | C12: Ataléia | D12: =VLOOKUP(B12,Planilha1!$A:$B,2,0) -> Vale do Mucuri | E12: Municipal | F12: - | G12: - | H12: - | I12: - | J12: - | K12: - | L12: - | M12: 74.2 | N12: 94.9 | O12: 63.9 | P12: 67.1 | Q12: 73.1 | R12: 70 | S12: 0.724054 | T12: 81.5 | U12: 85.4 | V12: 93.9 | W12: 61.1 | X12: 97 | Y12: 78.1 | Z12: 0.808548 | AA12: 91.3 | AB12: 91.5 | AC12: 97 | AD12: 83 | AE12: 93 | AF12: 92.1 | AG12: 0.910799 | AH12: 97.8 | AI12: 98.6 | AJ12: 99.2 | AK12: 97.8 | AL12: 95.8 | AM12: 97.2 | AN12: 0.977057 | AO12: 97.6 | AP12: 99 | AQ12: 98.3 | AR12: 100 | AS12: 98.8 | AT12: 91.4 | AU12: 0.973969 | AV12: 98.1 | AW12: 97.5 | AX12: 98.7 | AY12: 100 | AZ12: 100 | BA12: 94.4 | BB12: 0.980751 | BC12: 100 | BD12: 100 | BE12: 100 | BF12: 100 | BG12: 100 | BH12: 100 | BI12: 1 | BJ12: 99.5 | BK12: 100 | BL12: 100 | BM12: 99 | BN12: 100 | BO12: 98.5 | BP12: 0.99496 | BQ12: 100 | BR12: 100 | BS12: 100 | BT12: 100 | BU12: 100 | BV12: 100 | BW12: 1 | BX12: - | BY12: - | BZ12: - | CA12: 178.81 | CB12: 159.51 | CC12: 4.276639 | CD12: 206.78 | CE12: 182.32 | CF12: 5.225145 | CG12: 206.32 | CH12: 189.74 | CI12: 5.351276 | CJ12: 198.8 | CK12: 182.44 | CL12: 5.075037 | CM12: 237,51 | CN12: 214,42 | CO12: 6.395232 | CP12: 210.48 | CQ12: 209.45 | CR12: 5.789028 | CS12: 211.12 | CT12: 205.2 | CU12: 5.723969 | CV12: 192.27 | CW12: 179 | CX12: 4.887873 | CY12: 198.98 | CZ12: 196.8 | DA12: 5.339563 | DB12: - | DC12: 3.1 | DD12: 4.2 | DE12: 4.9 | DF12: 5 | DG12: 6.2 | DH12: 5.7 | DI12: 5.7 | DJ12: 4.9 | DK12: 5.3 | DL12: - | DM12: 3.3 | DN12: 3.6 | DO12: 3.9 | DP12: 4.2 | DQ12: 4.5 | DR12: 4.8 | DS12: 5.1 | DU12: =DK12-DS12 -> 0.2
A13: MG | B13: 3106606 | C13: Bertópolis | D13: =VLOOKUP(B13,Planilha1!$A:$B,2,0) -> Vale do Mucuri | E13: Municipal | F13: 79.7 | G13: - | H13: 82.5 | I13: 70.5 | J13: 81.7 | K13: 81.7 | L13: 0.787628 | M13: 66.5 | N13: 53.4 | O13: 78.4 | P13: 66.7 | Q13: 90 | R13: 51 | S13: 0.647726 | T13: 85.7 | U13: 100 | V13: 96 | W13: 67.9 | X13: 93.3 | Y13: 82.4 | Z13: 0.862095 | AA13: 99.6 | AB13: 100 | AC13: 100 | AD13: 98.6 | AE13: 100 | AF13: 100 | AG13: 0.997168 | AH13: 99.2 | AI13: 100 | AJ13: 100 | AK13: 100 | AL13: 96.6 | AM13: 100 | AN13: 0.99301 | AO13: 99.5 | AP13: 100 | AQ13: 100 | AR13: 100 | AS13: 100 | AT13: 97.9 | AU13: 0.995728 | AV13: 99.6 | AW13: 100 | AX13: 100 | AY13: 100 | AZ13: 100 | BA13: 97.5 | BB13: 0.994898 | BC13: 100 | BD13: 100 | BE13: 100 | BF13: 100 | BG13: 100 | BH13: 100 | BI13: 1 | BJ13: 100 | BK13: 100 | BL13: 100 | BM13: 100 | BN13: 100 | BO13: 100 | BP13: 1 | BQ13: 100 | BR13: 100 | BS13: 100 | BT13: 100 | BU13: 100 | BV13: 100 | BW13: 1 | BX13: 164.8 | BY13: 162 | BZ13: 4.057899 | CA13: 174.1 | CB13: 154.56 | CC13: 4.096754 | CD13: 198.35 | CE13: 178.92 | CF13: 5.002449 | CG13: 218.64 | CH13: 194.7 | CI13: 5.676572 | CJ13: 218.88 | CK13: 194.13 | CL13: 5.670788 | CM13: 223,20 | CN13: 215,10 | CO13: 6.134504 | CP13: 216.07 | CQ13: 213.28 | CR13: 5.965344 | CS13: 225.79 | CT13: 213.35 | CU13: 6.152113 | CV13: ND | CW13: ND | CX13: - | CY13: 212.32 | CZ13: 207.88 | DA13: 5.795598 | DB13: 3.2 | DC13: 2.7 | DD13: 4.3 | DE13: 5.7 | DF13: 5.6 | DG13: 6.1 | DH13: 5.9 | DI13: 6.2 | DJ13: - | DK13: 5.8 | DL13: 3.3 | DM13: 3.6 | DN13: 4 | DO13: 4.3 | DP13: 4.6 | DQ13: 4.9 | DR13: 5.2 | DS13: 5.5 | DU13: =DK13-DS13 -> 0.3
A14: MG | B14: 3113701 | C14: Carlos Chagas | D14: =VLOOKUP(B14,Planilha1!$A:$B,2,0) -> Vale do Mucuri | E14: Municipal | F14: 76.9 | G14: 85 | H14: 64.5 | I14: 74.3 | J14: 82.3 | K14: 82.8 | L14: 0.769758 | M14: 93.2 | N14: 98.9 | O14: 97.2 | P14: 83.9 | Q14: 98.3 | R14: 86.2 | S14: 0.924349 | T14: 92.8 | U14: 98.3 | V14: 98.1 | W14: 82.3 | X14: 99.3 | Y14: 89.2 | Z14: 0.929393 | AA14: 92.6 | AB14: 96.8 | AC14: 99.6 | AD14: 80.9 | AE14: 98.8 | AF14: 90.5 | AG14: 0.927595 | AH14: 96.3 | AI14: 96.3 | AJ14: 96.8 | AK14: 97.1 | AL14: 97.7 | AM14: 94 | AN14: 0.963629 | AO14: 95.1 | AP14: 97.8 | AQ14: 98.9 | AR14: 89.3 | AS14: 99 | AT14: 91.4 | AU14: 0.950999 | AV14: 95.6 | AW14: 96.9 | AX14: 98.2 | AY14: 90.4 | AZ14: 98.7 | BA14: 96.1 | BB14: 0.959643 | BC14: 92.8 | BD14: 98 | BE14: 100 | BF14: 83.6 | BG14: 99.1 | BH14: 86.6 | BI14: 0.9293 | BJ14: 97.5 | BK14: 98.8 | BL14: 97.2 | BM14: 98.1 | BN14: 97.1 | BO14: 96.5 | BP14: 0.975333 | BQ14: 96 | BR14: 100 | BS14: 97.3 | BT14: 90.4 | BU14: 95.8 | BV14: 96.2 | BW14: 0.958353 | BX14: 174 | BY14: 166 | BZ14: 4.302464 | CA14: 185.17 | CB14: 167.21 | CC14: 4.538013 | CD14: 216.32 | CE14: 195.57 | CF14: 5.648115 | CG14: 210.74 | CH14: 204.35 | CI14: 5.701263 | CJ14: 208.12 | CK14: 197.43 | CL14: 5.525445 | CM14: 217,62 | CN14: 203,90 | CO14: 5.824379 | CP14: 221.77 | CQ14: 213.6 | CR14: 6.079941 | CS14: 211.28 | CT14: 200.62 | CU14: 5.64375 | CV14: 195.21 | CW14: 190.74 | CX14: 5.157434 | CY14: 198.88 | CZ14: 197.11 | DA14: 5.343291 | DB14: 3.3 | DC14: 4.2 | DD14: 5.2 | DE14: 5.3 | DF14: 5.3 | DG14: 5.5 | DH14: 5.8 | DI14: 5.2 | DJ14: 5 | DK14: 5.1 | DL14: 3.4 | DM14: 3.7 | DN14: 4.1 | DO14: 4.4 | DP14: 4.7 | DQ14: 5 | DR14: 5.3 | DS14: 5.6 | DU14: =DK14-DS14 -> -0.5
A15: MG | B15: 3115458 | C15: Catuji | D15: =VLOOKUP(B15,Planilha1!$A:$B,2,0) -> Vale do Mucuri | E15: Municipal | F15: - | G15: - | H15: - | I15: - | J15: - | K15: - | L15: - | M15: 63.4 | N15: 91.6 | O15: 53.9 | P15: 55.5 | Q15: 61.5 | R15: 62.9 | S15: 0.627775 | T15: 76 | U15: 93.9 | V15: 63 | W15: 78.1 | X15: 72.8 | Y15: 80.6 | Z15: 0.763709 | AA15: 96.3 | AB15: 96.8 | AC15: 98.1 | AD15: 97.3 | AE15: 95.6 | AF15: 94 | AG15: 0.963386 | AH15: 97.1 | AI15: 96.8 | AJ15: 98.1 | AK15: 97.2 | AL15: 97 | AM15: 96.7 | AN15: 0.971574 | AO15: 99.5 | AP15: 100 | AQ15: 99.3 | AR15: 100 | AS15: 99 | AT15: 99.3 | AU15: 0.995183 | AV15: 99.5 | AW15: 99.2 | AX15: 100 | AY15: 100 | AZ15: 99.2 | BA15: 99.2 | BB15: 0.995185 | BC15: 99.8 | BD15: 99 | BE15: 100 | BF15: 100 | BG15: 100 | BH15: 100 | BI15: 0.997984 | BJ15: 100 | BK15: 100 | BL15: 100 | BM15: 100 | BN15: 100 | BO15: 100 | BP15: 1 | BQ15: 100 | BR15: 100 | BS15: 100 | BT15: 100 | BU15: 100 | BV15: 100 | BW15: 1 | BX15: - | BY15: - | BZ15: - | CA15: 192.49 | CB15: 179.12 | CC15: 4.894253 | CD15: 209.36 | CE15: 183.45 | CF15: 5.294927 | CG15: 218.95 | CH15: 192.67 | CI15: 5.645579 | CJ15: 200.63 | CK15: 189.99 | CL15: 5.247233 | CM15: 210,39 | CN15: 193,16 | CO15: 5.491129 | CP15: 202.41 | CQ15: 192.08 | CR15: 5.319203 | CS15: 183.74 | CT15: 165.87 | CU15: 4.486359 | CV15: 189.06 | CW15: 175.44 | CX15: 4.761886 | CY15: 198.79 | CZ15: 198.89 | DA15: 5.373937 | DB15: - | DC15: 3.1 | DD15: 4 | DE15: 5.4 | DF15: 5.1 | DG15: 5.5 | DH15: 5.3 | DI15: 4.5 | DJ15: 4.8 | DK15: 5.4 | DL15: - | DM15: 3.4 | DN15: 3.7 | DO15: 4 | DP15: 4.3 | DQ15: 4.6 | DR15: 4.9 | DS15: 5.2 | DU15: =DK15-DS15 -> 0.2
A16: MG | B16: 3120151 | C16: Crisólita | D16: =VLOOKUP(B16,Planilha1!$A:$B,2,0) -> Vale do Mucuri | E16: Municipal | F16: 71.2 | G16: 97.7 | H16: 53 | I16: 72.8 | J16: 75 | K16: 79.1 | L16: 0.726584 | M16: 86.8 | N16: 96.1 | O16: 88.1 | P16: 72.7 | Q16: 94.3 | R16: 82.8 | S16: 0.859203 | T16: 82 | U16: 79.8 | V16: 90.9 | W16: 69.5 | X16: 90.9 | Y16: 85.1 | Z16: 0.824091 | AA16: 94.8 | AB16: 97.3 | AC16: 96.7 | AD16: 94.8 | AE16: 93.8 | AF16: 91.4 | AG16: 0.947523 | AH16: 98.5 | AI16: 98.8 | AJ16: 97.2 | AK16: 96.4 | AL16: 100 | AM16: 100 | AN16: 0.984582 | AO16: 96.4 | AP16: 94.6 | AQ16: 97.7 | AR16: 92.3 | AS16: 98.9 | AT16: 98.9 | AU16: 0.96408 | AV16: 97.4 | AW16: 98.9 | AX16: 98.6 | AY16: 97.4 | AZ16: 95.7 | BA16: 96.8 | BB16: 0.974658 | BC16: 97.5 | BD16: 97.3 | BE16: 93.1 | BF16: 97.7 | BG16: 98.6 | BH16: 100 | BI16: 0.972838 | BJ16: 96.4 | BK16: 98.6 | BL16: 100 | BM16: 98.4 | BN16: 98.3 | BO16: 89.4 | BP16: 0.967807 | BQ16: 100 | BR16: 100 | BS16: 100 | BT16: 100 | BU16: 100 | BV16: 100 | BW16: 1 | BX16: 157.6 | BY16: 149 | BZ16: 3.682223 | CA16: 174.28 | CB16: 163.83 | CC16: 4.268734 | CD16: 179.91 | CE16: 158.77 | CF16: 4.284177 | CG16: 199.81 | CH16: 184.64 | CI16: 5.134312 | CJ16: 196.19 | CK16: 178.39 | CL16: 4.951591 | CM16: 201,67 | CN16: 185,47 | CO16: 5.184899 | CP16: 197.43 | CQ16: 189.49 | CR16: 5.177074 | CS16: 192.62 | CT16: 185.35 | CU16: 5.010007 | CV16: 179.93 | CW16: 175.41 | CX16: 4.587104 | CY16: 192.55 | CZ16: 183.25 | DA16: 4.970489 | DB16: 2.7 | DC16: 3.7 | DD16: 3.5 | DE16: 4.9 | DF16: 4.9 | DG16: 5 | DH16: 5 | DI16: 4.9 | DJ16: 4.4 | DK16: 5 | DL16: 2.7 | DM16: 3.1 | DN16: 3.5 | DO16: 3.7 | DP16: 4 | DQ16: 4.3 | DR16: 4.6 | DS16: 5 | DU16: =DK16-DS16 -> 0
A17: MG | B17: 3126752 | C17: Franciscópolis | D17: =VLOOKUP(B17,Planilha1!$A:$B,2,0) -> Vale do Mucuri | E17: Municipal | F17: 62.5 | G17: 93.1 | H17: 46.8 | I17: 51.9 | J17: 66.1 | K17: 70.7 | L17: 0.619968 | M17: 83.1 | N17: 92.8 | O17: 86.5 | P17: 83.7 | Q17: 70.1 | R17: 80.2 | S17: 0.819428 | T17: 87 | U17: 96.1 | V17: 95.7 | W17: 73.7 | X17: 95.3 | Y17: 85.2 | Z17: 0.882551 | AA17: 97.8 | AB17: 98.3 | AC17: 100 | AD17: 98 | AE17: 99.2 | AF17: 94.9 | AG17: 0.980487 | AH17: 98.6 | AI17: 100 | AJ17: 100 | AK17: 98.6 | AL17: 97.8 | AM17: 97.2 | AN17: 0.987069 | AO17: 98.8 | AP17: 100 | AQ17: 100 | AR17: 96.3 | AS17: 98.4 | AT17: 100 | AU17: 0.989182 | AV17: 97.1 | AW17: 100 | AX17: 100 | AY17: 85.5 | AZ17: 98.9 | BA17: 100 | BB17: 0.965118 | BC17: 100 | BD17: 100 | BE17: 100 | BF17: 100 | BG17: 100 | BH17: 100 | BI17: 1 | BJ17: 99.6 | BK17: 100 | BL17: 100 | BM17: 100 | BN17: 100 | BO17: 98.3 | BP17: 0.996553 | BQ17: 99.5 | BR17: 98 | BS17: 100 | BT17: 100 | BU17: 100 | BV17: 100 | BW17: 0.995935 | BX17: 189.8 | BY17: 173.4 | BZ17: 4.736118 | CA17: 185.52 | CB17: 172.67 | CC17: 4.643965 | CD17: 188.54 | CE17: 176.79 | CF17: 4.776508 | CG17: 218.91 | CH17: 193.9 | CI17: 5.667179 | CJ17: 211.29 | CK17: 204.59 | CL17: 5.716123 | CM17: 208,09 | CN17: 216,83 | CO17: 5.8776 | CP17: 203.56 | CQ17: 195.47 | CR17: 5.402786 | CS17: 200.48 | CT17: 190.78 | CU17: 5.258734 | CV17: ND | CW17: ND | CX17: - | CY17: 208.9 | CZ17: 191.58 | DA17: 5.433967 | DB17: 2.9 | DC17: 3.8 | DD17: 4.2 | DE17: 5.6 | DF17: 5.6 | DG17: 5.8 | DH17: 5.2 | DI17: 5.3 | DJ17: - | DK17: 5.4 | DL17: 3 | DM17: 3.4 | DN17: 3.9 | DO17: 4.2 | DP17: 4.5 | DQ17: 4.8 | DR17: 5.1 | DS17: 5.4 | DU17: =DK17-DS17 -> 0
A18: MG | B18: 3126802 | C18: Frei Gaspar | D18: =VLOOKUP(B18,Planilha1!$A:$B,2,0) -> Vale do Mucuri | E18: Municipal | F18: - | G18: - | H18: - | I18: - | J18: - | K18: - | L18: - | M18: - | N18: - | O18: - | P18: - | Q18: - | R18: - | S18: - | T18: - | U18: - | V18: - | W18: - | X18: - | Y18: - | Z18: - | AA18: - | AB18: - | AC18: - | AD18: - | AE18: - | AF18: - | AG18: - | AH18: 97.3 | AI18: 100 | AJ18: 100 | AK18: 100 | AL18: 100 | AM18: 88.4 | AN18: 0.974427 | AO18: 93.2 | AP18: 100 | AQ18: 100 | AR18: 94.3 | AS18: 100 | AT18: 79.7 | AU18: 0.940707 | AV18: 99.7 | AW18: 98.5 | AX18: 100 | AY18: 100 | AZ18: 100 | BA18: 100 | BB18: 0.996964 | BC18: 96.9 | BD18: 100 | BE18: 95.3 | BF18: 100 | BG18: 100 | BH18: 90.1 | BI18: 0.969143 | BJ18: 100 | BK18: 100 | BL18: 100 | BM18: 100 | BN18: 100 | BO18: 100 | BP18: 1 | BQ18: 99.1 | BR18: 98.7 | BS18: 100 | BT18: 100 | BU18: 100 | BV18: 97.5 | BW18: 0.992297 | BX18: - | BY18: - | BZ18: - | CA18: - | CB18: - | CC18: - | CD18: - | CE18: - | CF18: - | CG18: - | CH18: - | CI18: - | CJ18: 246.94 | CK18: 225.4 | CL18: 6.77483 | CM18: 218,13 | CN18: 211,19 | CO18: 5.966657 | CP18: 219.36 | CQ18: 203.88 | CR18: 5.857221 | CS18: 224.35 | CT18: 208.59 | CU18: 6.038087 | CV18: ND | CW18: ND | CX18: - | CY18: 203.24 | CZ18: 190.24 | DA18: 5.301588 | DB18: - | DC18: - | DD18: - | DE18: - | DF18: 6.6 | DG18: 5.6 | DH18: 5.8 | DI18: 5.9 | DJ18: - | DK18: 5.3 | DL18: - | DM18: - | DN18: - | DO18: - | DP18: 6.8 | DQ18: 7 | DR18: 7.2 | DS18: 7.4 | DU18: =DK18-DS18 -> -2.1
A19: MG | B19: 3127057 | C19: Fronteira dos Vales | D19: =VLOOKUP(B19,Planilha1!$A:$B,2,0) -> Vale do Mucuri | E19: Municipal | F19: 86.1 | G19: 95.8 | H19: 78.7 | I19: 86.4 | J19: 85.9 | K19: 88 | L19: 0.86619 | M19: 83.7 | N19: 96.8 | O19: 80 | P19: 80.3 | Q19: 79.6 | R19: 83.7 | S19: 0.836203 | T19: 94.2 | U19: 97.1 | V19: 100 | W19: 91.9 | X19: 98.6 | Y19: 78.1 | Z19: 0.923768 | AA19: 97.3 | AB19: 100 | AC19: 97.3 | AD19: 94 | AE19: 98.8 | AF19: 98.2 | AG19: 0.976171 | AH19: - | AI19: - | AJ19: - | AK19: - | AL19: - | AM19: - | AN19: - | AO19: - | AP19: - | AQ19: - | AR19: - | AS19: - | AT19: - | AU19: - | AV19: 99.6 | AW19: 100 | AX19: 100 | AY19: 100 | AZ19: 97.5 | BA19: 100 | BB19: 0.994898 | BC19: 100 | BD19: 100 | BE19: 100 | BF19: 100 | BG19: 100 | BH19: 100 | BI19: 1 | BJ19: 100 | BK19: 100 | BL19: 100 | BM19: 100 | BN19: 100 | BO19: 100 | BP19: 1 | BQ19: 100 | BR19: 100 | BS19: 100 | BT19: 100 | BU19: 100 | BV19: 100 | BW19: 1 | BX19: 144.2 | BY19: 142.4 | BZ19: 3.304879 | CA19: 181.34 | CB19: 153.68 | CC19: 4.218922 | CD19: 177.57 | CE19: 160.39 | CF19: 4.268975 | CG19: 182.72 | CH19: 169.93 | CI19: 4.540712 | CJ19: - | CK19: - | CL19: - | CM19: - | CN19: - | CO19: - | CP19: 213.36 | CQ19: 209.62 | CR19: 5.847081 | CS19: 203.07 | CT19: 201.23 | CU19: 5.498162 | CV19: ND | CW19: ND | CX19: - | CY19: 166.13 | CZ19: 160.32 | DA19: 4.049382 | DB19: 2.9 | DC19: 3.5 | DD19: 3.9 | DE19: 4.4 | DF19: - | DG19: - | DH19: 5.8 | DI19: 5.5 | DJ19: - | DK19: 4 | DL19: 2.9 | DM19: 3.3 | DN19: 3.7 | DO19: 3.9 | DP19: 4.2 | DQ19: 4.5 | DR19: 4.8 | DS19: 5.1 | DU19: =DK19-DS19 -> -1.1
A20: MG | B20: 3132305 | C20: Itaipé | D20: =VLOOKUP(B20,Planilha1!$A:$B,2,0) -> Vale do Mucuri | E20: Municipal | F20: - | G20: - | H20: - | I20: - | J20: - | K20: - | L20: - | M20: - | N20: - | O20: - | P20: - | Q20: - | R20: - | S20: - | T20: 69.7 | U20: 81.3 | V20: 56.2 | W20: 68.4 | X20: 77.9 | Y20: 75 | Z20: 0.705379 | AA20: 84.4 | AB20: 90.9 | AC20: 95.8 | AD20: 73.6 | AE20: 78.7 | AF20: 81.2 | AG20: 0.832664 | AH20: 93.7 | AI20: 98 | AJ20: 94.7 | AK20: 95.8 | AL20: 88.4 | AM20: 92.1 | AN20: 0.936818 | AO20: 99.4 | AP20: 99.4 | AQ20: 100 | AR20: 99.5 | AS20: 100 | AT20: 98.8 | AU20: 0.99538 | AV20: 100 | AW20: 100 | AX20: 100 | AY20: 100 | AZ20: 100 | BA20: 100 | BB20: 1 | BC20: 99.7 | BD20: 100 | BE20: 100 | BF20: 100 | BG20: 99.2 | BH20: 99.3 | BI20: 0.996986 | BJ20: 99.8 | BK20: 99 | BL20: 100 | BM20: 100 | BN20: 100 | BO20: 100 | BP20: 0.997984 | BQ20: 99 | BR20: 100 | BS20: 99 | BT20: 100 | BU20: 97.7 | BV20: 98.1 | BW20: 0.989509 | BX20: - | BY20: - | BZ20: - | CA20: - | CB20: - | CC20: - | CD20: 197.56 | CE20: 171.83 | CF20: 4.858464 | CG20: 208.96 | CH20: 187.84 | CI20: 5.367112 | CJ20: 222.04 | CK20: 191.22 | CL20: 5.678185 | CM20: 202,65 | CN20: 184,28 | CO20: 5.181965 | CP20: 205.76 | CQ20: 190.51 | CR20: 5.354588 | CS20: 194.84 | CT20: 183.43 | CU20: 5.017464 | CV20: ND | CW20: ND | CX20: - | CY20: 201.9 | CZ20: 191.1 | DA20: 5.291652 | DB20: - | DC20: - | DD20: 3.4 | DE20: 4.5 | DF20: 5.3 | DG20: 5.2 | DH20: 5.4 | DI20: 5 | DJ20: - | DK20: 5.2 | DL20: - | DM20: - | DN20: 3.7 | DO20: 4 | DP20: 4.3 | DQ20: 4.6 | DR20: 4.9 | DS20: 5.2 | DU20: =DK20-DS20 -> 0
A21: MG | B21: 3138906 | C21: Machacalis | D21: =VLOOKUP(B21,Planilha1!$A:$B,2,0) -> Vale do Mucuri | E21: Municipal | F21: 78.5 | G21: 94.7 | H21: 64 | I21: 80.8 | J21: 79.9 | K21: 85.7 | L21: 0.796874 | M21: 79.2 | N21: 100 | O21: 66.2 | P21: 72.6 | Q21: 80.1 | R21: 81 | S21: 0.784807 | T21: 87.4 | U21: 100 | V21: 90 | W21: 73.8 | X21: 94.2 | Y21: 77 | Z21: 0.858163 | AA21: 81.5 | AB21: 92.9 | AC21: 95 | AD21: 58.9 | AE21: 98.9 | AF21: 82 | AG21: 0.825425 | AH21: 97 | AI21: 95 | AJ21: 99 | AK21: 99 | AL21: 99 | AM21: 92.7 | AN21: 0.968676 | AO21: 98.9 | AP21: 100 | AQ21: 100 | AR21: 97.7 | AS21: 99 | AT21: 97.6 | AU21: 0.988488 | AV21: 100 | AW21: 100 | AX21: 100 | AY21: 100 | AZ21: 100 | BA21: 100 | BB21: 1 | BC21: 99.4 | BD21: 100 | BE21: 98.2 | BF21: 100 | BG21: 100 | BH21: 98.6 | BI21: 0.993536 | BJ21: 99.7 | BK21: 100 | BL21: 98.8 | BM21: 100 | BN21: 100 | BO21: 100 | BP21: 0.997577 | BQ21: 100 | BR21: 100 | BS21: 100 | BT21: 100 | BU21: 100 | BV21: 100 | BW21: 1 | BX21: 176.8 | BY21: 165.8 | BZ21: 4.351362 | CA21: 203.87 | CB21: 187.4 | CC21: 5.261974 | CD21: 217.47 | CE21: 198.66 | CF21: 5.726244 | CG21: 241.78 | CH21: 218.96 | CI21: 6.559266 | CJ21: 229.78 | CK21: 213.55 | CL21: 6.231895 | CM21: 217,65 | CN21: 201,51 | CO21: 5.781497 | CP21: 214.89 | CQ21: 206.51 | CR21: 5.819734 | CS21: 232.18 | CT21: 220.23 | CU21: 6.399151 | CV21: 195.12 | CW21: 186.02 | CX21: 5.069899 | CY21: 214.05 | CZ21: 208.06 | DA21: 5.831885 | DB21: 3.5 | DC21: 4.1 | DD21: 4.9 | DE21: 5.4 | DF21: 6 | DG21: 5.7 | DH21: 5.8 | DI21: 6.4 | DJ21: 5.1 | DK21: 5.8 | DL21: 3.5 | DM21: 3.9 | DN21: 4.3 | DO21: 4.6 | DP21: 4.9 | DQ21: 5.1 | DR21: 5.4 | DS21: 5.7 | DU21: =DK21-DS21 -> 0.1
A22: MG | B22: 3139201 | C22: Malacacheta | D22: =VLOOKUP(B22,Planilha1!$A:$B,2,0) -> Vale do Mucuri | E22: Municipal | F22: 68.7 | G22: 79.8 | H22: 76.2 | I22: 58.5 | J22: 71.2 | K22: 61.4 | L22: 0.684179 | M22: 72.6 | N22: 79.8 | O22: 74.3 | P22: 64.2 | Q22: 77.5 | R22: 65.9 | S22: 0.717933 | T22: 78.4 | U22: 69.6 | V22: 83.8 | W22: 71 | X22: 91.3 | Y22: 82.6 | Z22: 0.788085 | AA22: 86.6 | AB22: 82.7 | AC22: 89.7 | AD22: 72.3 | AE22: 95.1 | AF22: 94.8 | AG22: 0.860064 | AH22: 95.5 | AI22: 92.5 | AJ22: 98.8 | AK22: 89.2 | AL22: 98.9 | AM22: 99.1 | AN22: 0.9552 | AO22: 98.4 | AP22: 98.6 | AQ22: 100 | AR22: 94.3 | AS22: 100 | AT22: 99.1 | AU22: 0.983531 | AV22: 92.1 | AW22: 91.7 | AX22: 89.4 | AY22: 87.9 | AZ22: 97.5 | BA22: 92.6 | BB22: 0.917046 | BC22: 88.7 | BD22: 96.6 | BE22: 93.8 | BF22: 77.6 | BG22: 94 | BH22: 80.6 | BI22: 0.878043 | BJ22: 99.5 | BK22: 100 | BL22: 100 | BM22: 100 | BN22: 100 | BO22: 97.2 | BP22: 0.994272 | BQ22: 99.1 | BR22: 98.6 | BS22: 100 | BT22: 98.3 | BU22: 98.7 | BV22: 100 | BW22: 0.991146 | BX22: 180.2 | BY22: 171.6 | BZ22: 4.522784 | CA22: 186.95 | CB22: 173.9 | CC22: 4.693619 | CD22: 227.7 | CE22: 194.85 | CF22: 5.8522 | CG22: 216.54 | CH22: 201.82 | CI22: 5.76595 | CJ22: 232.71 | CK22: 204.95 | CL22: 6.131447 | CM22: 195,90 | CN22: 189,30 | CO22: 5.144421 | CP22: 201.99 | CQ22: 201.44 | CR22: 5.481369 | CS22: 198.62 | CT22: 188.42 | CU22: 5.180329 | CV22: 204.03 | CW22: 191.04 | CX22: 5.33121 | CY22: 216.09 | CZ22: 204.19 | DA22: 5.800453 | DB22: 3.1 | DC22: 3.4 | DD22: 4.6 | DE22: 5 | DF22: 5.9 | DG22: 5.1 | DH22: 5 | DI22: 4.5 | DJ22: 5.3 | DK22: 5.7 | DL22: 3.2 | DM22: 3.5 | DN22: 3.9 | DO22: 4.2 | DP22: 4.5 | DQ22: 4.8 | DR22: 5.1 | DS22: 5.4 | DU22: =DK22-DS22 -> 0.3
A23: MG | B23: 3144300 | C23: Nanuque | D23: =VLOOKUP(B23,Planilha1!$A:$B,2,0) -> Vale do Mucuri | E23: Municipal | F23: 78.9 | G23: 90.9 | H23: 65 | I23: 79.5 | J23: 80.1 | K23: 84.3 | L23: 0.789751 | M23: 79.9 | N23: 91.5 | O23: 74.1 | P23: 70.6 | Q23: 80.5 | R23: 81.9 | S23: 0.790877 | T23: 76.5 | U23: 78.3 | V23: 67.4 | W23: 81.3 | X23: 76.1 | Y23: 85.4 | Z23: 0.772099 | AA23: 82.9 | AB23: 83.2 | AC23: 74.7 | AD23: 84.4 | AE23: 84.7 | AF23: 89.5 | AG23: 0.830096 | AH23: 98.8 | AI23: 99.4 | AJ23: 98.7 | AK23: 99 | AL23: 97.4 | AM23: 99.4 | AN23: 0.987744 | AO23: 93.1 | AP23: 100 | AQ23: 96.2 | AR23: 86.1 | AS23: 92.2 | AT23: 92.8 | AU23: 0.932292 | AV23: 90 | AW23: 98 | AX23: 95.5 | AY23: 81.9 | AZ23: 89 | BA23: 88.3 | BB23: 0.901774 | BC23: 95.2 | BD23: 100 | BE23: 94.9 | BF23: 93.9 | BG23: 94.2 | BH23: 92.9 | BI23: 0.951167 | BJ23: 96.6 | BK23: 96.3 | BL23: 96.9 | BM23: 98.1 | BN23: 98 | BO23: 93.9 | BP23: 0.966155 | BQ23: 99.3 | BR23: 100 | BS23: 100 | BT23: 100 | BU23: 100 | BV23: 95.8 | BW23: 0.991308 | BX23: 165 | BY23: 157.4 | BZ23: 3.972663 | CA23: 168.52 | CB23: 151.41 | CC23: 3.932992 | CD23: 197.26 | CE23: 178.93 | CF23: 4.981829 | CG23: 194.96 | CH23: 183.02 | CI23: 5.0123 | CJ23: 197.95 | CK23: 184.6 | CL23: 5.098088 | CM23: 190,49 | CN23: 181,03 | CO23: 4.890813 | CP23: 194.89 | CQ23: 192.7 | CR23: 5.186964 | CS23: 191.71 | CT23: 188.39 | CU23: 5.047913 | CV23: 178.98 | CW23: 179.58 | CX23: 4.644793 | CY23: 183.86 | CZ23: 176.83 | DA23: 4.687922 | DB23: 3.1 | DC23: 3.1 | DD23: 3.8 | DE23: 4.2 | DF23: 5 | DG23: 4.6 | DH23: 4.7 | DI23: 4.8 | DJ23: 4.5 | DK23: 4.6 | DL23: 3.2 | DM23: 3.5 | DN23: 3.9 | DO23: 4.2 | DP23: 4.5 | DQ23: 4.8 | DR23: 5.1 | DS23: 5.4 | DU23: =DK23-DS23 -> -0.8
A24: MG | B24: 3145356 | C24: Novo Oriente de Minas | D24: =VLOOKUP(B24,Planilha1!$A:$B,2,0) -> Vale do Mucuri | E24: Municipal | F24: - | G24: - | H24: - | I24: - | J24: - | K24: - | L24: - | M24: - | N24: - | O24: - | P24: - | Q24: - | R24: - | S24: - | T24: - | U24: - | V24: - | W24: - | X24: - | Y24: - | Z24: - | AA24: 91.3 | AB24: 94.6 | AC24: 97.1 | AD24: 82.8 | AE24: 94.6 | AF24: 90.2 | AG24: 0.915683 | AH24: 96.8 | AI24: 98.8 | AJ24: 99.2 | AK24: 94.2 | AL24: 99.3 | AM24: 92.6 | AN24: 0.967353 | AO24: 95.6 | AP24: 99 | AQ24: 98.1 | AR24: 97.6 | AS24: 98.3 | AT24: 84.8 | AU24: 0.952272 | AV24: 99.6 | AW24: 100 | AX24: 100 | AY24: 99.1 | AZ24: 100 | BA24: 98.9 | BB24: 0.995975 | BC24: 95.4 | BD24: 100 | BE24: 98.9 | BF24: 91 | BG24: 96.4 | BH24: 91.7 | BI24: 0.954585 | BJ24: 99.8 | BK24: 98.9 | BL24: 100 | BM24: 100 | BN24: 100 | BO24: 100 | BP24: 0.99778 | BQ24: 96.7 | BR24: 100 | BS24: 100 | BT24: 88.8 | BU24: 100 | BV24: 93.6 | BW24: 0.962556 | BX24: - | BY24: - | BZ24: - | CA24: - | CB24: - | CC24: - | CD24: - | CE24: - | CF24: - | CG24: 202.74 | CH24: 182.54 | CI24: 5.152046 | CJ24: 215.68 | CK24: 196.47 | CL24: 5.652265 | CM24: 204,25 | CN24: 205,09 | CO24: 5.590863 | CP24: 227.86 | CQ24: 212.82 | CR24: 6.181981 | CS24: 206.04 | CT24: 208.41 | CU24: 5.685387 | CV24: ND | CW24: ND | CX24: - | CY24: 186.72 | CZ24: 184.67 | DA24: 4.885048 | DB24: - | DC24: - | DD24: - | DE24: 4.7 | DF24: 5.5 | DG24: 5.3 | DH24: 6.2 | DI24: 5.4 | DJ24: - | DK24: 4.7 | DL24: - | DM24: - | DN24: - | DO24: 5 | DP24: 5.3 | DQ24: 5.5 | DR24: 5.8 | DS24: 6.1 | DU24: =DK24-DS24 -> -1.4
A25: MG | B25: 3146206 | C25: Ouro Verde de Minas | D25: =VLOOKUP(B25,Planilha1!$A:$B,2,0) -> Vale do Mucuri | E25: Municipal | F25: - | G25: - | H25: - | I25: - | J25: - | K25: - | L25: - | M25: - | N25: - | O25: - | P25: - | Q25: - | R25: - | S25: - | T25: - | U25: - | V25: - | W25: - | X25: - | Y25: - | Z25: - | AA25: - | AB25: - | AC25: - | AD25: - | AE25: - | AF25: - | AG25: - | AH25: - | AI25: - | AJ25: - | AK25: - | AL25: - | AM25: - | AN25: - | AO25: - | AP25: - | AQ25: - | AR25: - | AS25: - | AT25: - | AU25: - | AV25: 98.8 | AW25: 98.4 | AX25: 100 | AY25: 100 | AZ25: 96.2 | BA25: 100 | BB25: 0.988971 | BC25: - | BD25: - | BE25: - | BF25: - | BG25: - | BH25: - | BI25: - | BJ25: 100 | BK25: 100 | BL25: 100 | BM25: 100 | BN25: 100 | BO25: 100 | BP25: 1 | BQ25: 100 | BR25: 100 | BS25: 100 | BT25: 100 | BU25: 100 | BV25: 100 | BW25: 1 | BX25: - | BY25: - | BZ25: - | CA25: - | CB25: - | CC25: - | CD25: - | CE25: - | CF25: - | CG25: - | CH25: - | CI25: - | CJ25: - | CK25: - | CL25: - | CM25: - | CN25: - | CO25: - | CP25: 179.36 | CQ25: 159.23 | CR25: 4.282044 | CS25: - | CT25: - | CU25: - | CV25: 167.03 | CW25: 156.26 | CX25: 3.992739 | CY25: 210.35 | CZ25: 201.78 | DA25: 5.647093 | DB25: - | DC25: - | DD25: - | DE25: - | DF25: - | DG25: - | DH25: 4.2 | DI25: - | DJ25: 4 | DK25: 5.6 | DL25: - | DM25: - | DN25: - | DO25: - | DP25: - | DQ25: - | DR25: 4.5 | DS25: 4.8 | DU25: =DK25-DS25 -> 0.8
A26: MG | B26: 3148509 | C26: Pavão | D26: =VLOOKUP(B26,Planilha1!$A:$B,2,0) -> Vale do Mucuri | E26: Municipal | F26: 78.1 | G26: 96.9 | H26: 86.5 | I26: 62.4 | J26: 78.7 | K26: 74 | L26: 0.779712 | M26: 84.6 | N26: 98.9 | O26: 97.4 | P26: 75 | Q26: 83.8 | R26: 70.5 | S26: 0.835714 | T26: 84.2 | U26: 100 | V26: 97.5 | W26: 61.2 | X26: 96 | Y26: 76.5 | Z26: 0.832157 | AA26: 95.5 | AB26: 100 | AC26: 100 | AD26: 88.2 | AE26: 100 | AF26: 89.6 | AG26: 0.952407 | AH26: 93.2 | AI26: 100 | AJ26: 100 | AK26: 87.2 | AL26: 94.1 | AM26: 89.7 | AN26: 0.939088 | AO26: 97 | AP26: 100 | AQ26: 100 | AR26: 86.8 | AS26: 98 | AT26: 98.3 | AU26: 0.963433 | AV26: 98.9 | AW26: 100 | AX26: 98.4 | AY26: 100 | AZ26: 100 | BA26: 95.7 | BB26: 0.98791 | BC26: 100 | BD26: 100 | BE26: 100 | BF26: 100 | BG26: 100 | BH26: 100 | BI26: 1 | BJ26: 100 | BK26: 100 | BL26: 100 | BM26: 100 | BN26: 100 | BO26: 100 | BP26: 1 | BQ26: 97.6 | BR26: 100 | BS26: 100 | BT26: 93.3 | BU26: 100 | BV26: 93.2 | BW26: 0.97186 | BX26: 176.6 | BY26: 175.6 | BZ26: 4.528109 | CA26: 212.08 | CB26: 197.8 | CC26: 5.607745 | CD26: 226.24 | CE26: 205.21 | CF26: 6.012701 | CG26: 222.29 | CH26: 197.8 | CI26: 5.802592 | CJ26: 220.09 | CK26: 210.24 | CL26: 5.986789 | CM26: 234,14 | CN26: 232,83 | CO26: 6.665646 | CP26: 209.8 | CQ26: 198.19 | CR26: 5.571324 | CS26: 228.12 | CT26: 220.27 | CU26: 6.322397 | CV26: ND | CW26: ND | CX26: - | CY26: 202.92 | CZ26: 202.06 | DA26: 5.51039 | DB26: 3.5 | DC26: 4.7 | DD26: 5 | DE26: 5.5 | DF26: 5.6 | DG26: 6.4 | DH26: 5.5 | DI26: 6.3 | DJ26: - | DK26: 5.4 | DL26: 3.6 | DM26: 3.9 | DN26: 4.4 | DO26: 4.6 | DP26: 4.9 | DQ26: 5.2 | DR26: 5.5 | DS26: 5.8 | DU26: =DK26-DS26 -> -0.4
A27: MG | B27: 3152402 | C27: Poté | D27: =VLOOKUP(B27,Planilha1!$A:$B,2,0) -> Vale do Mucuri | E27: Municipal | F27: 85.9 | G27: 97.3 | H27: 99.1 | I27: 71.5 | J27: 96.4 | K27: 70.9 | L27: 0.849876 | M27: 84.7 | N27: 94.8 | O27: 88.3 | P27: 68.2 | Q27: 96.6 | R27: 80.7 | S27: 0.843457 | T27: 86.3 | U27: 96.8 | V27: 95.7 | W27: 75.4 | X27: 94.7 | Y27: 75.1 | Z27: 0.863293 | AA27: 87.7 | AB27: 91.3 | AC27: 97 | AD27: 75.3 | AE27: 97.5 | AF27: 82.9 | AG27: 0.879329 | AH27: 96.7 | AI27: 98 | AJ27: 98.7 | AK27: 95.5 | AL27: 98.6 | AM27: 93 | AN27: 0.967087 | AO27: 95.9 | AP27: 98.8 | AQ27: 97.4 | AR27: 89.6 | AS27: 100 | AT27: 95.1 | AU27: 0.96035 | AV27: 97 | AW27: 99.4 | AX27: 99.3 | AY27: 92.3 | AZ27: 98.6 | BA27: 95.9 | BB27: 0.970222 | BC27: 95.4 | BD27: 97.8 | BE27: 85.9 | BF27: 96.9 | BG27: 100 | BH27: 96 | BI27: 0.950517 | BJ27: 99.3 | BK27: 100 | BL27: 100 | BM27: 97.9 | BN27: 100 | BO27: 99.3 | BP27: 0.994332 | BQ27: 98.1 | BR27: 100 | BS27: 98.1 | BT27: 100 | BU27: 100 | BV27: 94.4 | BW27: 0.984506 | BX27: 174.4 | BY27: 160.6 | BZ27: 4.21157 | CA27: 174.19 | CB27: 157.63 | CC27: 4.154289 | CD27: 189.34 | CE27: 170.95 | CF27: 4.685593 | CG27: 202.3 | CH27: 186.56 | CI27: 5.21674 | CJ27: 199.58 | CK27: 187.77 | CL27: 5.186831 | CM27: 210,59 | CN27: 195,35 | CO27: 5.534764 | CP27: 204.2 | CQ27: 194.71 | CR27: 5.401181 | CS27: 202.38 | CT27: 192.54 | CU27: 5.326994 | CV27: 187.19 | CW27: 181.96 | CX27: 4.844745 | CY27: 201.72 | CZ27: 196.45 | DA27: 5.385489 | DB27: 3.6 | DC27: 3.5 | DD27: 4 | DE27: 4.6 | DF27: 5 | DG27: 5.3 | DH27: 5.2 | DI27: 5.1 | DJ27: 4.8 | DK27: 5.3 | DL27: 3.6 | DM27: 4 | DN27: 4.4 | DO27: 4.7 | DP27: 5 | DQ27: 5.3 | DR27: 5.5 | DS27: 5.8 | DU27: =DK27-DS27 -> -0.5
A28: MG | B28: 3157658 | C28: Santa Helena de Minas | D28: =VLOOKUP(B28,Planilha1!$A:$B,2,0) -> Vale do Mucuri | E28: Municipal | F28: 83.7 | G28: 82.7 | H28: 87.5 | I28: 79.5 | J28: 96 | K28: 72.9 | L28: 0.830107 | M28: 88.8 | N28: 93.1 | O28: 93.7 | P28: 86.1 | Q28: 98.1 | R28: 72.2 | S28: 0.876086 | T28: 88.8 | U28: 91.1 | V28: 83.5 | W28: 88.5 | X28: 95 | Y28: 86.6 | Z28: 0.887688 | AA28: 99.2 | AB28: 100 | AC28: 98.6 | AD28: 100 | AE28: 100 | AF28: 97.6 | AG28: 0.992302 | AH28: 99.4 | AI28: 98.6 | AJ28: 100 | AK28: 98.2 | AL28: 100 | AM28: 100 | AN28: 0.993536 | AO28: 100 | AP28: 100 | AQ28: 100 | AR28: 100 | AS28: 100 | AT28: 100 | AU28: 1 | AV28: 99.2 | AW28: 100 | AX28: 100 | AY28: 100 | AZ28: 97.6 | BA28: 98.4 | BB28: 0.991896 | BC28: 100 | BD28: 100 | BE28: 100 | BF28: 100 | BG28: 100 | BH28: 100 | BI28: 1 | BJ28: 100 | BK28: 100 | BL28: 100 | BM28: 100 | BN28: 100 | BO28: 100 | BP28: 1 | BQ28: 100 | BR28: 100 | BS28: 100 | BT28: 100 | BU28: 100 | BV28: 100 | BW28: 1 | BX28: 173.2 | BY28: 156.4 | BZ28: 4.111214 | CA28: 172.41 | CB28: 138.37 | CC28: 3.770138 | CD28: 210.16 | CE28: 179.44 | CF28: 5.237285 | CG28: 223.87 | CH28: 193.55 | CI28: 5.755472 | CJ28: 210.04 | CK28: 189.87 | CL28: 5.424632 | CM28: 222,98 | CN28: 198,41 | CO28: 5.826851 | CP28: 219 | CQ28: 210.66 | CR28: 5.973624 | CS28: 227.9 | CT28: 202.53 | CU28: 5.995653 | CV28: 218.36 | CW28: 215.65 | CX28: 6.052137 | CY28: 234.6 | CZ28: 225.15 | DA28: 6.534788 | DB28: 3.4 | DC28: 3.3 | DD28: 4.6 | DE28: 5.7 | DF28: 5.4 | DG28: 5.8 | DH28: 5.9 | DI28: 6 | DJ28: 6.1 | DK28: 6.5 | DL28: 3.5 | DM28: 3.8 | DN28: 4.2 | DO28: 4.5 | DP28: 4.8 | DQ28: 5.1 | DR28: 5.4 | DS28: 5.7 | DU28: =DK28-DS28 -> 0.8
A29: MG | B29: 3166709 | C29: Serra dos Aimorés | D29: =VLOOKUP(B29,Planilha1!$A:$B,2,0) -> Vale do Mucuri | E29: Municipal | F29: 82 | G29: 90.7 | H29: 82 | I29: 76.7 | J29: 82.3 | K29: 81.9 | L29: 0.824824 | M29: 76.5 | N29: 93.1 | O29: 81.6 | P29: 62.1 | Q29: 69.6 | R29: 75.5 | S29: 0.749491 | T29: 86.2 | U29: 98 | V29: 85.5 | W29: 76.8 | X29: 84.4 | Y29: 90.5 | Z29: 0.864769 | AA29: 93.2 | AB29: 100 | AC29: 96.8 | AD29: 83.3 | AE29: 98 | AF29: 92.2 | AG29: 0.936585 | AH29: 99 | AI29: 100 | AJ29: 95.6 | AK29: 98.8 | AL29: 100 | AM29: 100 | AN29: 0.9885 | AO29: 98.3 | AP29: 98.8 | AQ29: 100 | AR29: 97.8 | AS29: 95.2 | AT29: 100 | AU29: 0.983272 | AV29: 99.3 | AW29: 100 | AX29: 100 | AY29: 100 | AZ29: 100 | BA29: 97.2 | BB29: 0.994272 | BC29: 100 | BD29: 100 | BE29: 100 | BF29: 100 | BG29: 100 | BH29: 100 | BI29: 1 | BJ29: 100 | BK29: 100 | BL29: 100 | BM29: 100 | BN29: 100 | BO29: 100 | BP29: 1 | BQ29: 100 | BR29: 100 | BS29: 100 | BT29: 100 | BU29: 100 | BV29: 100 | BW29: 1 | BX29: 163.8 | BY29: 166 | BZ29: 4.106889 | CA29: 161.42 | CB29: 147.79 | CC29: 3.731678 | CD29: 207.57 | CE29: 181.75 | CF29: 5.229858 | CG29: 198.58 | CH29: 180.24 | CI29: 5.030838 | CJ29: 216.85 | CK29: 204.24 | CL29: 5.815866 | CM29: 211,50 | CN29: 208,78 | CO29: 5.796312 | CP29: 212.06 | CQ29: 206.61 | CR29: 5.767545 | CS29: 208.41 | CT29: 206.2 | CU29: 5.690434 | CV29: 205.78 | CW29: 194.33 | CX29: 5.424425 | CY29: 212.94 | CZ29: 210.81 | DA29: 5.860702 | DB29: 3.4 | DC29: 2.8 | DD29: 4.5 | DE29: 4.7 | DF29: 5.7 | DG29: 5.7 | DH29: 5.7 | DI29: 5.7 | DJ29: 5.4 | DK29: 5.9 | DL29: 3.5 | DM29: 3.8 | DN29: 4.2 | DO29: 4.5 | DP29: 4.8 | DQ29: 5.1 | DR29: 5.4 | DS29: 5.6 | DU29: =DK29-DS29 -> 0.3
A30: MG | B30: 3168606 | C30: Teófilo Otoni | D30: =VLOOKUP(B30,Planilha1!$A:$B,2,0) -> Vale do Mucuri | E30: Municipal | F30: 80.2 | G30: - | H30: 72.1 | I30: 81.1 | J30: 80.7 | K30: 86.8 | L30: 0.798206 | M30: 83.4 | N30: 98.2 | O30: 75.5 | P30: 82.4 | Q30: 78.3 | R30: 85.6 | S30: 0.833085 | T30: 85.8 | U30: 97.6 | V30: 77.1 | W30: 84.4 | X30: 84.4 | Y30: 87.2 | Z30: 0.856448 | AA30: 89.9 | AB30: 99.6 | AC30: 83.7 | AD30: 85.9 | AE30: 88.8 | AF30: 94.2 | AG30: 0.900803 | AH30: 97.2 | AI30: 99.8 | AJ30: 99.2 | AK30: 99.5 | AL30: 92.6 | AM30: 95.2 | AN30: 0.971737 | AO30: 95.6 | AP30: 99.6 | AQ30: 99.8 | AR30: 99.7 | AS30: 86.5 | AT30: 93.7 | AU30: 0.955596 | AV30: 95.4 | AW30: 99 | AX30: 99.6 | AY30: 99.1 | AZ30: 88.8 | BA30: 91.9 | BB30: 0.95466 | BC30: 95.8 | BD30: 99.6 | BE30: 99.7 | BF30: 100 | BG30: 88 | BH30: 93 | BI30: 0.958101 | BJ30: 95.2 | BK30: 100 | BL30: 99.8 | BM30: 98 | BN30: 90.2 | BO30: 88.8 | BP30: 0.951079 | BQ30: 95.9 | BR30: 99.9 | BS30: 99.9 | BT30: 99.7 | BU30: 91.9 | BV30: 89.6 | BW30: 0.959836 | BX30: 191.8 | BY30: 186 | BZ30: 5.00623 | CA30: 191.19 | CB30: 172.97 | CC30: 4.757626 | CD30: 216.82 | CE30: 197.19 | CF30: 5.687112 | CG30: 222.04 | CH30: 207.38 | CI30: 5.972003 | CJ30: 219.71 | CK30: 209.58 | CL30: 5.967537 | CM30: 225,94 | CN30: 220,51 | CO30: 6.285158 | CP30: 222.97 | CQ30: 219.65 | CR30: 6.212842 | CS30: 224.44 | CT30: 214.37 | CU30: 6.144895 | CV30: 213.72 | CW30: 207.27 | CX30: 5.811224 | CY30: 221.17 | CZ30: 213.34 | DA30: 6.063763 | DB30: 4 | DC30: 4 | DD30: 4.9 | DE30: 5.4 | DF30: 5.8 | DG30: 6 | DH30: 5.9 | DI30: 5.9 | DJ30: 5.5 | DK30: 5.8 | DL30: 4.1 | DM30: 4.4 | DN30: 4.8 | DO30: 5.1 | DP30: 5.4 | DQ30: 5.6 | DR30: 5.9 | DS30: 6.2 | DU30: =DK30-DS30 -> -0.4
A31: MG | B31: 3170305 | C31: Umburatiba | D31: =VLOOKUP(B31,Planilha1!$A:$B,2,0) -> Vale do Mucuri | E31: Municipal | F31: - | G31: - | H31: - | I31: - | J31: - | K31: - | L31: - | M31: 86.4 | N31: 92.3 | O31: 85.5 | P31: 89.3 | Q31: 87.8 | R31: 73.9 | S31: 0.85252 | T31: 91.9 | U31: 98.1 | V31: 97.4 | W31: 75.8 | X31: 98.4 | Y31: 90.6 | Z31: 0.911521 | AA31: 86.9 | AB31: 88.4 | AC31: 98.5 | AD31: 71.7 | AE31: 100 | AF31: 85.7 | AG31: 0.875962 | AH31: 99.3 | AI31: 100 | AJ31: 98.3 | AK31: 100 | AL31: 100 | AM31: 98.5 | AN31: 0.993538 | AO31: 99.2 | AP31: 100 | AQ31: 100 | AR31: 97.7 | AS31: 100 | AT31: 98.5 | AU31: 0.992306 | AV31: 94.4 | AW31: 100 | AX31: 97.1 | AY31: 87.8 | AZ31: 98 | BA31: 92.2 | BB31: 0.948078 | BC31: 95.8 | BD31: 100 | BE31: 97.3 | BF31: 94.9 | BG31: 100 | BH31: 88.4 | BI31: 0.959194 | BJ31: 100 | BK31: 100 | BL31: 100 | BM31: 100 | BN31: 100 | BO31: 100 | BP31: 1 | BQ31: 99.4 | BR31: 97 | BS31: 100 | BT31: 100 | BU31: 100 | BV31: 100 | BW31: 0.993852 | BX31: - | BY31: - | BZ31: - | CA31: 181.75 | CB31: 153.99 | CC31: 4.232382 | CD31: 197.24 | CE31: 183.03 | CF31: 5.055993 | CG31: 197.15 | CH31: 178.92 | CI31: 4.979548 | CJ31: 218.56 | CK31: 194.23 | CL31: 5.6665 | CM31: 199,11 | CN31: 188,95 | CO31: 5.199316 | CP31: 212.86 | CQ31: 204.91 | CR31: 5.751903 | CS31: 202.71 | CT31: 190.2 | CU31: 5.290746 | CV31: 176.97 | CW31: 179.16 | CX31: 4.598797 | CY31: 191.13 | CZ31: 185 | DA31: 4.975208 | DB31: - | DC31: 3.6 | DD31: 4.6 | DE31: 4.4 | DF31: 5.6 | DG31: 5.2 | DH31: 5.5 | DI31: 5.1 | DJ31: 4.6 | DK31: 4.9 | DL31: - | DM31: 3.8 | DN31: 4.1 | DO31: 4.4 | DP31: 4.7 | DQ31: 5 | DR31: 5.3 | DS31: 5.6 | DU31: =DK31-DS31 -> -0.7
A33: Fonte: MEC/Inep
A34: Notas: ND - Número de participantes no SAEB insuficiente para que os resultados sejam divulgados;
A35: ND* - Solicitação de não divulgação conforme Portaria Inep nº 410 de 03 de novembro de 2011 ou Portaria Inep nº 304 de 24 de junho de 2013;
A36: ND*** - Município com pelo menos 20% do material extraviado, com participação insuficiente para divulgação dos resultados;
A37: (*) - Média calculada a partir dos resultados das escolas nas avaliações estaduais, em decorrência de extravio das provas retornadas e impossibilidade do cálculo da proficiência para o SAEB;
A38: (**) - Média calculada a partir dos resultados dos alunos no SAEB com participação inferior a 50%, em decorrência de extravio de provas;
A39: (1) - Médias do SAEB 2011 e Ideb 2011 calculados sem as escolas federais;
A40: (2) Ver Nota informativa do Ideb de 2021 (https://download.inep.gov.br/educacao_basica/portal_ideb/planilhas_para_download/2021/nota_informativa_ideb_2021.pdf) e
A41: Relatório de Resultados do Saeb de 2021 (https://download.inep.gov.br/educacao_basica/saeb/2021/resultados/relatorio_de_resultados_do_saeb_2021_volume_1.pdf)
A42: para maiores informações sobre o impacto da pandemia no Ideb;
A43: (3) O primeiro ciclo do Ideb considera as metas pactuadas no Compromisso Todos pela Educação (https://www.planalto.gov.br/ccivil_03/_ato2007-2010/2007/decreto/d6094.htm)
...

Sheet Planilha1
A1: Código Município Completo | B1: Mesorregião
A2: 3100906 | B2: Vale do Mucuri
A3: 3104700 | B3: Vale do Mucuri
A4: 3106606 | B4: Vale do Mucuri
A5: 3113701 | B5: Vale do Mucuri
A6: 3115458 | B6: Vale do Mucuri
A7: 3120151 | B7: Vale do Mucuri
A8: 3126752 | B8: Vale do Mucuri
A9: 3126802 | B9: Vale do Mucuri
A10: 3127057 | B10: Vale do Mucuri
A11: 3132305 | B11: Vale do Mucuri
A12: 3137007 | B12: Vale do Mucuri
A13: 3138906 | B13: Vale do Mucuri
... A24: 3170305 | B24: Vale do Mucuri
