Workbook

Sheet DB
B1: GASTO POR ALUNO DO EF - SIOPE
A2: KEY | B2: COD_ENTE | C2: MUN | D2: NUM_ANO | E2: NUM_PERI | F2: COD_INDI | G2: COD_EXIB | H2: CATEG | I2: INDICADOR | J2: VAL_INDI
A3: =C3&D3&G3 -> Águas Formosas20151.1 | B3: 3100906 | C3: Águas Formosas | D3: 2015 | E3: 1 | F3: 24 | G3: 1.1 | H3: Indicador legal | I3: 1.1 - Percentual de aplicação das receitas de impostos e transferências vinculadas à educação em MDE (mínimo de 25% para estados, DF e municípios) | J3: 0.282
A4: =C4&D4&G4 -> Águas Formosas20151.2 | B4: 3100906 | C4: Águas Formosas | D4: 2015 | E4: 1 | F4: 67 | G4: 1.2 | H4: Indicador legal | I4: 1.2 - Percentual de aplicação do FUNDEB na remuneração dos profissionais da educação (mínimo de 70%) - Inciso XXII, Portaria Conjunta MGI/MF/CGU Nº 33 de30-08-2023 | J4: 0.7194
A5: =C5&D5&G5 -> Águas Formosas20151.3 | B5: 3100906 | C5: Águas Formosas | D5: 2015 | E5: 1 | F5: 68 | G5: 1.3 | H5: Indicador legal | I5: 1.3 - Percentual de aplicação do FUNDEB em despesas com MDE, que não remuneração dos profissionais da educação (máximo de 30%) | J5: 0.2728
A6: =C6&D6&G6 -> Águas Formosas20152.1 | B6: 3100906 | C6: Águas Formosas | D6: 2015 | E6: 1 | F6: 28 | G6: 2.1 | H6: Indicador de dispêndio financeiro | I6: 2.1 - Percentual dos recursos do FUNDEB aplicados na educação infantil | J6: 0.2206
A7: =C7&D7&G7 -> Águas Formosas20152.2 | B7: 3100906 | C7: Águas Formosas | D7: 2015 | E7: 1 | F7: 29 | G7: 2.2 | H7: Indicador de dispêndio financeiro | I7: 2.2 - Percentual dos recursos do FUNDEB aplicados no ensino fundamental | J7: 0.6747
A8: =C8&D8&G8 -> Águas Formosas20152.4 | B8: 3100906 | C8: Águas Formosas | D8: 2015 | E8: 1 | F8: 31 | G8: 2.4 | H8: Indicador de dispêndio financeiro | I8: 2.4 - Percentual das despesas com educação infantil em relação à despesa total com educação | J8: 0.3711
A9: =C9&D9&G9 -> Águas Formosas20152.5 | B9: 3100906 | C9: Águas Formosas | D9: 2015 | E9: 1 | F9: 32 | G9: 2.5 | H9: Indicador de dispêndio financeiro | I9: 2.5 - Percentual das despesas com ensino fundamental em relação à despesa total com educação | J9: 0.5985
A10: =C10&D10&G10 -> Águas Formosas20152.8 | B10: 3100906 | C10: Águas Formosas | D10: 2015 | E10: 1 | F10: 35 | G10: 2.8 | H10: Indicador de dispêndio financeiro | I10: 2.8 - Percentual das despesas em educação em relação às despesas de todas as áreas | J10: 0.3087
A11: =C11&D11&G11 -> Águas Formosas20154.1 | B11: 3100906 | C11: Águas Formosas | D11: 2015 | E11: 1 | F11: 44 | G11: 4.1 | H11: Indicador de investimento por aluno | I11: 4.1 - Investimento educacional por aluno da educação infantil | J11: 4090.75
A12: =C12&D12&G12 -> Águas Formosas20154.10 | B12: 3100906 | C12: Águas Formosas | D12: 2015 | E12: 1 | F12: 58 | G12: 4.10 | H12: Indicador de investimento por aluno | I12: 4.10 - Despesa com professores por aluno da educação básica | J12: 2413.48
A13: =C13&D13&G13 -> Águas Formosas20154.11 | B13: 3100906 | C13: Águas Formosas | D13: 2015 | E13: 1 | F13: 59 | G13: 4.11 | H13: Indicador de investimento por aluno | I13: 4.11 - Despesas com profissionais não docentes da área educacional por aluno da educação básica | J13: 1824.29
A14: =C14&D14&G14 -> Águas Formosas20154.2 | B14: 3100906 | C14: Águas Formosas | D14: 2015 | E14: 1 | F14: 45 | G14: 4.2 | H14: Indicador de investimento por aluno | I14: 4.2 - Investimento educacional por aluno do ensino fundamental | J14: 10390.98
... A33: =C33&D33&G33 -> Bertópolis20151.3 | B33: 3106606 | C33: Bertópolis | D33: 2015 | E33: 1 | F33: 68 | G33: 1.3 | H33: Indicador legal | I33: 1.3 - Percentual de aplicação do FUNDEB em despesas com MDE, que não remuneração dos profissionais da educação (máximo de 30%) | J33: 0.1565
A34: =C34&D34&G34 -> Bertópolis20152.1 | B34: 3106606 | C34: Bertópolis | D34: 2015 | E34: 1 | F34: 28 | G34: 2.1 | H34: Indicador de dispêndio financeiro | I34: 2.1 - Percentual dos recursos do FUNDEB aplicados na educação infantil
A35: =C35&D35&G35 -> Bertópolis20152.2 | B35: 3106606 | C35: Bertópolis | D35: 2015 | E35: 1 | F35: 29 | G35: 2.2 | H35: Indicador de dispêndio financeiro | I35: 2.2 - Percentual dos recursos do FUNDEB aplicados no ensino fundamental | J35: 0.7323
A36: =C36&D36&G36 -> Bertópolis20152.4 | B36: 3106606 | C36: Bertópolis | D36: 2015 | E36: 1 | F36: 31 | G36: 2.4 | H36: Indicador de dispêndio financeiro | I36: 2.4 - Percentual das despesas com educação infantil em relação à despesa total com educação | J36: 0.1928
A37: =C37&D37&G37 -> Bertópolis20152.5 | B37: 3106606 | C37: Bertópolis | D37: 2015 | E37: 1 | F37: 32 | G37: 2.5 | H37: Indicador de dispêndio financeiro | I37: 2.5 - Percentual das despesas com ensino fundamental em relação à despesa total com educação | J37: 0.7742
A38: =C38&D38&G38 -> Bertópolis20152.8 | B38: 3106606 | C38: Bertópolis | D38: 2015 | E38: 1 | F38: 35 | G38: 2.8 | H38: Indicador de dispêndio financeiro | I38: 2.8 - Percentual das despesas em educação em relação às despesas de todas as áreas | J38: 0.2224
A39: =C39&D39&G39 -> Bertópolis20154.1 | B39: 3106606 | C39: Bertópolis | D39: 2015 | E39: 1 | F39: 44 | G39: 4.1 | H39: Indicador de investimento por aluno | I39: 4.1 - Investimento educacional por aluno da educação infantil | J39: 4123.82
A40: =C40&D40&G40 -> Bertópolis20154.10 | B40: 3106606 | C40: Bertópolis | D40: 2015 | E40: 1 | F40: 58 | G40: 4.10 | H40: Indicador de investimento por aluno | I40: 4.10 - Despesa com professores por aluno da educação básica | J40: 4240.52
A41: =C41&D41&G41 -> Bertópolis20154.11 | B41: 3106606 | C41: Bertópolis | D41: 2015 | E41: 1 | F41: 59 | G41: 4.11 | H41: Indicador de investimento por aluno | I41: 4.11 - Despesas com profissionais não docentes da área educacional por aluno da educação básica | J41: 706.77
A42: =C42&D42&G42 -> Bertópolis20154.2 | B42: 3106606 | C42: Bertópolis | D42: 2015 | E42: 1 | F42: 45 | G42: 4.2 | H42: Indicador de investimento por aluno | I42: 4.2 - Investimento educacional por aluno do ensino fundamental | J42: 8207.5
A43: =C43&D43&G43 -> Bertópolis20154.8 | B43: 3106606 | C43: Bertópolis | D43: 2015 | E43: 1 | F43: 56 | G43: 4.8 | H43: Indicador de investimento por aluno | I43: 4.8 - Investimento educacional por aluno da educação básica | J43: 6853.99
A44: =C44&D44&G44 -> Bertópolis20154.9 | B44: 3106606 | C44: Bertópolis | D44: 2015 | E44: 1 | F44: 57 | G44: 4.9 | H44: Indicador de investimento por aluno | I44: 4.9 - Investimento educacional por aluno | J44: 6853.99
A45: =C45&D45&G45 -> Carlos Chagas20151.1 | B45: 3113701 | C45: Carlos Chagas | D45: 2015 | E45: 1 | F45: 24 | G45: 1.1 | H45: Indicador legal | I45: 1.1 - Percentual de aplicação das receitas de impostos e transferências vinculadas à educação em MDE (mínimo de 25% para estados, DF e municípios) | J45: 0.3021
A46: =C46&D46&G46 -> Carlos Chagas20151.2 | B46: 3113701 | C46: Carlos Chagas | D46: 2015 | E46: 1 | F46: 67 | G46: 1.2 | H46: Indicador legal | I46: 1.2 - Percentual de aplicação do FUNDEB na remuneração dos profissionais da educação (mínimo de 70%) - Inciso XXII, Portaria Conjunta MGI/MF/CGU Nº 33 de30-08-2023 | J46: 0.8752
... A89: =C89&D89&G89 -> Franciscópolis20151.3 | B89: 3126752 | C89: Franciscópolis | D89: 2015 | E89: 1 | F89: 68 | G89: 1.3 | H89: Indicador legal | I89: 1.3 - Percentual de aplicação do FUNDEB em despesas com MDE, que não remuneração dos profissionais da educação (máximo de 30%) | J89: 0.3469
A90: =C90&D90&G90 -> Franciscópolis20152.1 | B90: 3126752 | C90: Franciscópolis | D90: 2015 | E90: 1 | F90: 28 | G90: 2.1 | H90: Indicador de dispêndio financeiro | I90: 2.1 - Percentual dos recursos do FUNDEB aplicados na educação infantil
A91: =C91&D91&G91 -> Franciscópolis20152.2 | B91: 3126752 | C91: Franciscópolis | D91: 2015 | E91: 1 | F91: 29 | G91: 2.2 | H91: Indicador de dispêndio financeiro | I91: 2.2 - Percentual dos recursos do FUNDEB aplicados no ensino fundamental | J91: 0.692
A92: =C92&D92&G92 -> Franciscópolis20152.4 | B92: 3126752 | C92: Franciscópolis | D92: 2015 | E92: 1 | F92: 31 | G92: 2.4 | H92: Indicador de dispêndio financeiro | I92: 2.4 - Percentual das despesas com educação infantil em relação à despesa total com educação | J92: 0.1278
A93: =C93&D93&G93 -> Franciscópolis20152.5 | B93: 3126752 | C93: Franciscópolis | D93: 2015 | E93: 1 | F93: 32 | G93: 2.5 | H93: Indicador de dispêndio financeiro | I93: 2.5 - Percentual das despesas com ensino fundamental em relação à despesa total com educação | J93: 0.8378
A94: =C94&D94&G94 -> Franciscópolis20152.8 | B94: 3126752 | C94: Franciscópolis | D94: 2015 | E94: 1 | F94: 35 | G94: 2.8 | H94: Indicador de dispêndio financeiro | I94: 2.8 - Percentual das despesas em educação em relação às despesas de todas as áreas | J94: 0.2421
A95: =C95&D95&G95 -> Franciscópolis20154.1 | B95: 3126752 | C95: Franciscópolis | D95: 2015 | E95: 1 | F95: 44 | G95: 4.1 | H95: Indicador de investimento por aluno | I95: 4.1 - Investimento educacional por aluno da educação infantil | J95: 3594.3
A96: =C96&D96&G96 -> Franciscópolis20154.10 | B96: 3126752 | C96: Franciscópolis | D96: 2015 | E96: 1 | F96: 58 | G96: 4.10 | H96: Indicador de investimento por aluno | I96: 4.10 - Despesa com professores por aluno da educação básica | J96: 1722.39
A97: =C97&D97&G97 -> Franciscópolis20154.11 | B97: 3126752 | C97: Franciscópolis | D97: 2015 | E97: 1 | F97: 59 | G97: 4.11 | H97: Indicador de investimento por aluno | I97: 4.11 - Despesas com profissionais não docentes da área educacional por aluno da educação básica | J97: 1439.11
A98: =C98&D98&G98 -> Franciscópolis20154.2 | B98: 3126752 | C98: Franciscópolis | D98: 2015 | E98: 1 | F98: 45 | G98: 4.2 | H98: Indicador de investimento por aluno | I98: 4.2 - Investimento educacional por aluno do ensino fundamental | J98: 6533.76
A99: =C99&D99&G99 -> Franciscópolis20154.8 | B99: 3126752 | C99: Franciscópolis | D99: 2015 | E99: 1 | F99: 56 | G99: 4.8 | H99: Indicador de investimento por aluno | I99: 4.8 - Investimento educacional por aluno da educação básica | J99: 5895.48
A100: =C100&D100&G100 -> Franciscópolis20154.9 | B100: 3126752 | C100: Franciscópolis | D100: 2015 | E100: 1 | F100: 57 | G100: 4.9 | H100: Indicador de investimento por aluno | I100: 4.9 - Investimento educacional por aluno | J100: 5895.48
...

Sheet INTEGRALIDADE
B1: 1.1 | C1: 1.1 | D1: 1.1 | E1: 1.1 | F1: 1.1 | G1: 1.1 | H1: 1.1 | I1: 1.1 | J1: 1.1 | K1: 1.1 | L1: 1.2 | M1: 1.2 | N1: 1.2 | O1: 1.2 | P1: 1.2 | Q1: 1.2 | R1: 1.2 | S1: 1.2 | T1: 1.2 | U1: 1.2 | V1: 1.3 | W1: 1.3 | X1: 1.3 | Y1: 1.3 | Z1: 1.3 | AA1: 1.3 | AB1: 1.3 | AC1: 1.3 | AD1: 1.3 | AE1: 1.3 | AF1: 2.1 | AG1: 2.1 | AH1: 2.1 | AI1: 2.1 | AJ1: 2.1 | AK1: 2.1 | AL1: 2.1 | AM1: 2.1 | AN1: 2.1 | AO1: 2.1 | AP1: 2.2 | AQ1: 2.2 | AR1: 2.2 | AS1: 2.2 | AT1: 2.2 | AU1: 2.2 | AV1: 2.2 | AW1: 2.2 | AX1: 2.2 | AY1: 2.2 | AZ1: 2.4 | BA1: 2.4 | BB1: 2.4 | BC1: 2.4 | BD1: 2.4 | BE1: 2.4 | BF1: 2.4 | BG1: 2.4 | BH1: 2.4 | BI1: 2.4 | BJ1: 2.5 | BK1: 2.5 | BL1: 2.5 | BM1: 2.5 | BN1: 2.5 | BO1: 2.5 | BP1: 2.5 | BQ1: 2.5 | BR1: 2.5 | BS1: 2.5 | BT1: 2.8 | BU1: 2.8 | BV1: 2.8 | BW1: 2.8 | BX1: 2.8 | BY1: 2.8 | BZ1: 2.8 | CA1: 2.8 | CB1: 2.8 | CC1: 2.8 | CD1: 4.1 | CE1: 4.1 | CF1: 4.1 | CG1: 4.1 | CH1: 4.1 | CI1: 4.1 | CJ1: 4.1 | CK1: 4.1 | CL1: 4.1 | CM1: 4.1 | CN1: 4.2 | CO1: 4.2 | CP1: 4.2 | CQ1: 4.2 | CR1: 4.2 | CS1: 4.2 | CT1: 4.2 | CU1: 4.2 | CV1: 4.2 | CW1: 4.2 | CX1: 4.8 | CY1: 4.8 | CZ1: 4.8 | DA1: 4.8 | DB1: 4.8 | DC1: 4.8 | DD1: 4.8 | DE1: 4.8 | DF1: 4.8 | DG1: 4.8 | DH1: 4.9 | DI1: 4.9 | DJ1: 4.9 | DK1: 4.9 | DL1: 4.9 | DM1: 4.9 | DN1: 4.9 | DO1: 4.9 | DP1: 4.9 | DQ1: 4.9 | DR1: 4.10 | DS1: 4.10 | DT1: 4.10 | DU1: 4.10 | DV1: 4.10 | DW1: 4.10 | DX1: 4.10 | DY1: 4.10 | DZ1: 4.10 | EA1: 4.10 | EB1: 4.11 | EC1: 4.11 | ED1: 4.11 | EE1: 4.11 | EF1: 4.11 | EG1: 4.11 | EH1: 4.11 | EI1: 4.11 | EJ1: 4.11 | EK1: 4.11
B2: 1.1 - Percentual de aplicação das receitas de impostos e transferências vinculadas à educação em MDE (mínimo de 25% para estados, DF e municípios) | L2: 1.2 - Percentual de aplicação do FUNDEB na remuneração dos profissionais da educação (mínimo de 70%) - Inciso XXII, Portaria Conjunta MGI/MF/CGU Nº 33 de30-08-2023 | V2: 1.3 - Percentual de aplicação do FUNDEB em despesas com MDE, que não remuneração dos profissionais da educação (máximo de 30%) | AF2: 2.1 - Percentual dos recursos do FUNDEB aplicados na educação infantil | AP2: 2.2 - Percentual dos recursos do FUNDEB aplicados no ensino fundamental | AZ2: 2.4 - Percentual das despesas com educação infantil em relação à despesa total com educação | BJ2: 2.5 - Percentual das despesas com ensino fundamental em relação à despesa total com educação | BT2: 2.8 - Percentual das despesas em educação em relação às despesas de todas as áreas | CD2: 4.1 - Investimento educacional por aluno da educação infantil | CN2: 4.2 - Investimento educacional por aluno do ensino fundamental | CX2: 4.8 - Investimento educacional por aluno da educação básica | DH2: 4.9 - Investimento educacional por aluno | DR2: 4.10 - Despesa com professores por aluno da educação básica | EB2: 4.11 - Despesas com profissionais não docentes da área educacional por aluno da educação básica
A3: CIDADE | B3: 2015 | C3: 2016 | D3: 2017 | E3: 2018 | F3: 2019 | G3: 2020 | H3: 2021 | I3: 2022 | J3: 2023 | K3: 2024 | L3: 2015 | M3: 2016 | N3: 2017 | O3: 2018 | P3: 2019 | Q3: 2020 | R3: 2021 | S3: 2022 | T3: 2023 | U3: 2024 | V3: 2015 | W3: 2016 | X3: 2017 | Y3: 2018 | Z3: 2019 | AA3: 2020 | AB3: 2021 | AC3: 2022 | AD3: 2023 | AE3: 2024 | AF3: 2015 | AG3: 2016 | AH3: 2017 | AI3: 2018 | AJ3: 2019 | AK3: 2020 | AL3: 2021 | AM3: 2022 | AN3: 2023 | AO3: 2024 | AP3: 2015 | AQ3: 2016 | AR3: 2017 | AS3: 2018 | AT3: 2019 | AU3: 2020 | AV3: 2021 | AW3: 2022 | AX3: 2023 | AY3: 2024 | AZ3: 2015 | BA3: 2016 | BB3: 2017 | BC3: 2018 | BD3: 2019 | BE3: 2020 | BF3: 2021 | BG3: 2022 | BH3: 2023 | BI3: 2024 | BJ3: 2015 | BK3: 2016 | BL3: 2017 | BM3: 2018 | BN3: 2019 | BO3: 2020 | BP3: 2021 | BQ3: 2022 | BR3: 2023 | BS3: 2024 | BT3: 2015 | BU3: 2016 | BV3: 2017 | BW3: 2018 | BX3: 2019 | BY3: 2020 | BZ3: 2021 | CA3: 2022 | CB3: 2023 | CC3: 2024 | CD3: 2015 | CE3: 2016 | CF3: 2017 | CG3: 2018 | CH3: 2019 | CI3: 2020 | CJ3: 2021 | CK3: 2022 | CL3: 2023 | CM3: 2024 | CN3: 2015 | CO3: 2016 | CP3: 2017 | CQ3: 2018 | CR3: 2019 | CS3: 2020 | CT3: 2021 | CU3: 2022 | CV3: 2023 | CW3: 2024 | CX3: 2015 | CY3: 2016 | CZ3: 2017 | DA3: 2018 | DB3: 2019 | DC3: 2020 | DD3: 2021 | DE3: 2022 | DF3: 2023 | DG3: 2024 | DH3: 2015 | DI3: 2016 | DJ3: 2017 | DK3: 2018 | DL3: 2019 | DM3: 2020 | DN3: 2021 | DO3: 2022 | DP3: 2023 | DQ3: 2024 | DR3: 2015 | DS3: 2016 | DT3: 2017 | DU3: 2018 | DV3: 2019 | DW3: 2020 | DX3: 2021 | DY3: 2022 | DZ3: 2023 | EA3: 2024 | EB3: 2015 | EC3: 2016 | ED3: 2017 | EE3: 2018 | EF3: 2019 | EG3: 2020 | EH3: 2021 | EI3: 2022 | EJ3: 2023 | EK3: 2024
A4: Águas Formosas | B4: =VLOOKUP($A4&B$3&B$1,DB!$A:$J,10,0) -> 0.282 | C4: =VLOOKUP($A4&C$3&C$1,DB!$A:$J,10,0) -> 0.2579 | D4: =VLOOKUP($A4&D$3&D$1,DB!$A:$J,10,0) -> 0.2814 | E4: =VLOOKUP($A4&E$3&E$1,DB!$A:$J,10,0) -> 0.2965 | F4: =VLOOKUP($A4&F$3&F$1,DB!$A:$J,10,0) -> 0.2877 | G4: =VLOOKUP($A4&G$3&G$1,DB!$A:$J,10,0) -> 0.2906 | H4: =VLOOKUP($A4&H$3&H$1,DB!$A:$J,10,0) -> 0.2092 | I4: =VLOOKUP($A4&I$3&I$1,DB!$A:$J,10,0) -> 0.261 | ... EK4: =VLOOKUP($A4&EK$3&EK$1,DB!$A:$J,10,0) -> 130.72
A5: Ataléia | B5: =VLOOKUP($A5&B$3&B$1,DB!$A:$J,10,0) -> 0.308 | C5: =VLOOKUP($A5&C$3&C$1,DB!$A:$J,10,0) -> 0.2876 | D5: =VLOOKUP($A5&D$3&D$1,DB!$A:$J,10,0) -> 0.2521 | E5: =VLOOKUP($A5&E$3&E$1,DB!$A:$J,10,0) -> 0.3451 | F5: =VLOOKUP($A5&F$3&F$1,DB!$A:$J,10,0) -> 0.2892 | G5: =VLOOKUP($A5&G$3&G$1,DB!$A:$J,10,0) -> 0.315 | H5: =VLOOKUP($A5&H$3&H$1,DB!$A:$J,10,0) -> 0.2389 | I5: =VLOOKUP($A5&I$3&I$1,DB!$A:$J,10,0) -> 0.2506 | ... EK5: =VLOOKUP($A5&EK$3&EK$1,DB!$A:$J,10,0) -> 44.7
A6: Bertópolis | B6: =VLOOKUP($A6&B$3&B$1,DB!$A:$J,10,0) -> 0.3032 | C6: =VLOOKUP($A6&C$3&C$1,DB!$A:$J,10,0) -> 0.2556 | D6: =VLOOKUP($A6&D$3&D$1,DB!$A:$J,10,0) -> 0.3447 | E6: =VLOOKUP($A6&E$3&E$1,DB!$A:$J,10,0) -> 0.2859 | F6: =VLOOKUP($A6&F$3&F$1,DB!$A:$J,10,0) -> 0.2701 | G6: =VLOOKUP($A6&G$3&G$1,DB!$A:$J,10,0) -> 0.2504 | H6: =VLOOKUP($A6&H$3&H$1,DB!$A:$J,10,0) -> 0.2065 | I6: =VLOOKUP($A6&I$3&I$1,DB!$A:$J,10,0) -> 0.2587 | ... EK6: =VLOOKUP($A6&EK$3&EK$1,DB!$A:$J,10,0) -> #N/A
A7: Carlos Chagas | B7: =VLOOKUP($A7&B$3&B$1,DB!$A:$J,10,0) -> 0.3021 | C7: =VLOOKUP($A7&C$3&C$1,DB!$A:$J,10,0) -> 0.3038 | D7: =VLOOKUP($A7&D$3&D$1,DB!$A:$J,10,0) -> 0.2969 | E7: =VLOOKUP($A7&E$3&E$1,DB!$A:$J,10,0) -> 0.3309 | F7: =VLOOKUP($A7&F$3&F$1,DB!$A:$J,10,0) -> 0.258 | G7: =VLOOKUP($A7&G$3&G$1,DB!$A:$J,10,0) -> 0.2435 | H7: =VLOOKUP($A7&H$3&H$1,DB!$A:$J,10,0) -> 0.2553 | I7: =VLOOKUP($A7&I$3&I$1,DB!$A:$J,10,0) -> 0.26 | ... EK7: =VLOOKUP($A7&EK$3&EK$1,DB!$A:$J,10,0) -> 519.81
A8: Catuji | B8: =VLOOKUP($A8&B$3&B$1,DB!$A:$J,10,0) -> 0.2571 | C8: =VLOOKUP($A8&C$3&C$1,DB!$A:$J,10,0) -> 0.2948 | D8: =VLOOKUP($A8&D$3&D$1,DB!$A:$J,10,0) -> 0.2632 | E8: =VLOOKUP($A8&E$3&E$1,DB!$A:$J,10,0) -> 0.2972 | F8: =VLOOKUP($A8&F$3&F$1,DB!$A:$J,10,0) -> 0.3544 | G8: =VLOOKUP($A8&G$3&G$1,DB!$A:$J,10,0) -> 0.2812 | H8: =VLOOKUP($A8&H$3&H$1,DB!$A:$J,10,0) -> 0.265 | I8: =VLOOKUP($A8&I$3&I$1,DB!$A:$J,10,0) -> 0.2731 | ... EK8: =VLOOKUP($A8&EK$3&EK$1,DB!$A:$J,10,0) -> 1498.24
A9: Crisólita | B9: =VLOOKUP($A9&B$3&B$1,DB!$A:$J,10,0) -> 0.2558 | C9: =VLOOKUP($A9&C$3&C$1,DB!$A:$J,10,0) -> 0.2993 | D9: =VLOOKUP($A9&D$3&D$1,DB!$A:$J,10,0) -> 0.2521 | E9: =VLOOKUP($A9&E$3&E$1,DB!$A:$J,10,0) -> 0.2554 | F9: =VLOOKUP($A9&F$3&F$1,DB!$A:$J,10,0) -> 0.2574 | G9: =VLOOKUP($A9&G$3&G$1,DB!$A:$J,10,0) -> 0.2582 | H9: =VLOOKUP($A9&H$3&H$1,DB!$A:$J,10,0) -> 0.256 | I9: =VLOOKUP($A9&I$3&I$1,DB!$A:$J,10,0) -> 0.2568 | ... EK9: =VLOOKUP($A9&EK$3&EK$1,DB!$A:$J,10,0) -> 1302.79
A10: Franciscópolis | B10: =VLOOKUP($A10&B$3&B$1,DB!$A:$J,10,0) -> 0.3083 | C10: =VLOOKUP($A10&C$3&C$1,DB!$A:$J,10,0) -> 0.2581 | D10: =VLOOKUP($A10&D$3&D$1,DB!$A:$J,10,0) -> 0.3273 | E10: =VLOOKUP($A10&E$3&E$1,DB!$A:$J,10,0) -> 0.3058 | F10: =VLOOKUP($A10&F$3&F$1,DB!$A:$J,10,0) -> 0.3288 | G10: =VLOOKUP($A10&G$3&G$1,DB!$A:$J,10,0) -> 0.2967 | H10: =VLOOKUP($A10&H$3&H$1,DB!$A:$J,10,0) -> 0.258 | I10: =VLOOKUP($A10&I$3&I$1,DB!$A:$J,10,0) -> 0.2842 | ... EK10: =VLOOKUP($A10&EK$3&EK$1,DB!$A:$J,10,0) -> 0
A11: Frei Gaspar | B11: =VLOOKUP($A11&B$3&B$1,DB!$A:$J,10,0) -> 0.2504 | C11: =VLOOKUP($A11&C$3&C$1,DB!$A:$J,10,0) -> 0.2877 | D11: =VLOOKUP($A11&D$3&D$1,DB!$A:$J,10,0) -> 0.3127 | E11: =VLOOKUP($A11&E$3&E$1,DB!$A:$J,10,0) -> 0.259 | F11: =VLOOKUP($A11&F$3&F$1,DB!$A:$J,10,0) -> 0.3349 | G11: =VLOOKUP($A11&G$3&G$1,DB!$A:$J,10,0) -> 0.2983 | H11: =VLOOKUP($A11&H$3&H$1,DB!$A:$J,10,0) -> 0.2732 | I11: =VLOOKUP($A11&I$3&I$1,DB!$A:$J,10,0) -> 0.3183 | ... EK11: =VLOOKUP($A11&EK$3&EK$1,DB!$A:$J,10,0) -> 1137.38
A12: Fronteira dos Vales | B12: =VLOOKUP($A12&B$3&B$1,DB!$A:$J,10,0) -> 0.32 | C12: =VLOOKUP($A12&C$3&C$1,DB!$A:$J,10,0) -> 0.3124 | D12: =VLOOKUP($A12&D$3&D$1,DB!$A:$J,10,0) -> 0.2609 | E12: =VLOOKUP($A12&E$3&E$1,DB!$A:$J,10,0) -> 0.2918 | F12: =VLOOKUP($A12&F$3&F$1,DB!$A:$J,10,0) -> 0.2875 | G12: =VLOOKUP($A12&G$3&G$1,DB!$A:$J,10,0) -> 0.2892 | H12: =VLOOKUP($A12&H$3&H$1,DB!$A:$J,10,0) -> 0.2466 | I12: =VLOOKUP($A12&I$3&I$1,DB!$A:$J,10,0) -> 0.275 | ... EK12: =VLOOKUP($A12&EK$3&EK$1,DB!$A:$J,10,0) -> 541.14
A13: Itaipé | B13: =VLOOKUP($A13&B$3&B$1,DB!$A:$J,10,0) -> 0.2524 | C13: =VLOOKUP($A13&C$3&C$1,DB!$A:$J,10,0) -> 0.2671 | D13: =VLOOKUP($A13&D$3&D$1,DB!$A:$J,10,0) -> 0.2896 | E13: =VLOOKUP($A13&E$3&E$1,DB!$A:$J,10,0) -> 0.251 | F13: =VLOOKUP($A13&F$3&F$1,DB!$A:$J,10,0) -> 0.2974 | G13: =VLOOKUP($A13&G$3&G$1,DB!$A:$J,10,0) -> 0.2566 | H13: =VLOOKUP($A13&H$3&H$1,DB!$A:$J,10,0) -> 0.2439 | I13: =VLOOKUP($A13&I$3&I$1,DB!$A:$J,10,0) -> 0.265 | ... EK13: =VLOOKUP($A13&EK$3&EK$1,DB!$A:$J,10,0) -> 0
A14: Ladainha | B14: =VLOOKUP($A14&B$3&B$1,DB!$A:$J,10,0) -> 0.2514 | C14: =VLOOKUP($A14&C$3&C$1,DB!$A:$J,10,0) -> 0.2872 | D14: =VLOOKUP($A14&D$3&D$1,DB!$A:$J,10,0) -> 0.2704 | E14: =VLOOKUP($A14&E$3&E$1,DB!$A:$J,10,0) -> 0.2779 | F14: =VLOOKUP($A14&F$3&F$1,DB!$A:$J,10,0) -> 0.3045 | G14: =VLOOKUP($A14&G$3&G$1,DB!$A:$J,10,0) -> 0.2771 | H14: =VLOOKUP($A14&H$3&H$1,DB!$A:$J,10,0) -> 0.2676 | I14: =VLOOKUP($A14&I$3&I$1,DB!$A:$J,10,0) -> 0.2731 | ... EK14: =VLOOKUP($A14&EK$3&EK$1,DB!$A:$J,10,0) -> 1744.7
A15: Machacalis | B15: =VLOOKUP($A15&B$3&B$1,DB!$A:$J,10,0) -> 0.2538 | C15: =VLOOKUP($A15&C$3&C$1,DB!$A:$J,10,0) -> 0.2991 | D15: =VLOOKUP($A15&D$3&D$1,DB!$A:$J,10,0) -> 0.2607 | E15: =VLOOKUP($A15&E$3&E$1,DB!$A:$J,10,0) -> 0.2935 | F15: =VLOOKUP($A15&F$3&F$1,DB!$A:$J,10,0) -> 0.2594 | G15: =VLOOKUP($A15&G$3&G$1,DB!$A:$J,10,0) -> 0.2791 | H15: =VLOOKUP($A15&H$3&H$1,DB!$A:$J,10,0) -> 0.2209 | I15: =VLOOKUP($A15&I$3&I$1,DB!$A:$J,10,0) -> 0.2602 | ... EK15: =VLOOKUP($A15&EK$3&EK$1,DB!$A:$J,10,0) -> #N/A
... A26: Umburatiba | B26: =VLOOKUP($A26&B$3&B$1,DB!$A:$J,10,0) -> 0.2686 | C26: =VLOOKUP($A26&C$3&C$1,DB!$A:$J,10,0) -> 0.2565 | D26: =VLOOKUP($A26&D$3&D$1,DB!$A:$J,10,0) -> 0.2955 | E26: =VLOOKUP($A26&E$3&E$1,DB!$A:$J,10,0) -> 0.2744 | F26: =VLOOKUP($A26&F$3&F$1,DB!$A:$J,10,0) -> 0.2645 | G26: =VLOOKUP($A26&G$3&G$1,DB!$A:$J,10,0) -> 0.2771 | H26: =VLOOKUP($A26&H$3&H$1,DB!$A:$J,10,0) -> 0.2217 | I26: =VLOOKUP($A26&I$3&I$1,DB!$A:$J,10,0) -> 0.2502 | ... EK26: =VLOOKUP($A26&EK$3&EK$1,DB!$A:$J,10,0) -> 0
